<mujoco model="humanoid">
  <compiler angle="degree" inertiafromgeom="true" coordinate="global" />
  <include file="./common/materials.xml" />
    <visual>
    <headlight ambient=".4 .4 .4" diffuse=".8 .8 .8" specular="0.3 0.3 0.3" />
    <map znear=".01" />
    <quality shadowsize="2048" />
  </visual>
  <default>
    <joint damping="0.0" armature="0.01" stiffness="0.0" limited="true" />
    <geom conaffinity="7" condim="1" contype="7" margin="0.001" material="self" rgba=".98 .54 .56 1." />
  </default>
  <statistic extent="3" center="0 0 1" />
  <option timestep="0.00222222222" />
  <asset>
    <texture type="skybox" file="./common/sky1.png" gridsize="3 4" gridlayout=".U..LFRB.D.." width="8192" height="8192" />
    <texture builtin="flat" height="1278" mark="cross" markrgb="1 1 1" name="texgeom" random="0.01" rgb1=".8 .6 .4" rgb2=".8 .6 .4" type="cube" width="127" />
  </asset>
  <worldbody>
    <light cutoff="100" diffuse="1 1 1" dir="-0 0 -1.3" directional="true" exponent="1" pos="0 0 1.3" specular=".1 .1 .1" />
    <geom condim="3" friction="1. .1 .1" material="grid_new" name="floor" pos="0.0 0.0 0.0" rgba=".8 .9 .8 1" size="113.40860504128673 113.40860504128673 0.2268172100825735" type="plane" />
    <body name="root" user="0.0000 -0.0000 0.0000" pos="0.0 -0.0 0.0">
      <joint armature="0.0" limited="false" name="root" pos="0.0 -0.0 0.0" stiffness="0" type="free" />
      <geom pos="0.0 0.0 -0.027218065209908816" size="0.12474946554541541" type="sphere" mass="8.8725" />
      <body name="lhipjoint" user="0.0963 -0.0494 -0.0918" pos="0.0 -0.0 0.0">
        <body name="lfemur" user="0.2274 -0.0494 -0.4521" pos="0.10921248665475912 -0.056023850890395646 -0.10410909942790122">
          <joint axis="0.0000 -1.0000 0.0000" name="lfemur_z" pos="0.10921248665475912 -0.056023850890395646 -0.10410909942790122" range="-60.0000 70.0000" type="hinge" />
          <joint axis="-0.3420 -0.0000 0.9397" name="lfemur_y" pos="0.10921248665475912 -0.056023850890395646 -0.10410909942790122" range="-70.0000 70.0000" type="hinge" />
          <joint axis="0.9397 0.0000 0.3420" name="lfemur_x" pos="0.10921248665475912 -0.056023850890395646 -0.10410909942790122" range="-160.0000 20.0000" type="hinge" />
          <geom fromto="0.11692427179756662 -0.056023850890395646 -0.12542991717566312 0.25017938272107854 -0.056023850890395646 -0.49139948564389546" size="0.0589724746214691" type="capsule" mass="10.8525" />
          <body name="ltibia" user="0.3657 -0.0494 -0.8321" pos="0.25789116786388605 -0.056023850890395646 -0.5127203033916573">
            <joint axis="0.9397 0.0000 0.3420" name="knee" pos="0.25789116786388605 -0.056023850890395646 -0.5127203033916573" range="0.0000 170.0000" type="hinge" />
            <geom contype="1" conaffinity="1" fromto="0.26571636161173484 -0.056023850890395646 -0.5340411211394193 0.4070234834931781 -0.056023850890395646 -0.9223521848007851" size="0.04196118386527609" type="capsule" mass="3.4274999999999998" />
            <body name="lfoot" user="0.3731 -0.1606 -0.8523" pos="0.41473526863598564 -0.056023850890395646 -0.9436730025485469">
              <geom contype="1" conaffinity="1" pos="0.42119955912333895 -0.11227451899087387 -0.9573954437585426" size="0.06804516302477204 0.1213472073941768 0.027218065209908816" quat="0.9848 -0.0000 -0.1736 0.0000" type="box" mass="0.9974999999999999" />
              <site name="load_force" type="box" pos="0.3714 -0.0990 -0.8442" size="0.0700 0.1170 0.0340" quat="0.9848 -0.0000 -0.1736 0.0000" rgba="0.8 0.2 .2 .4" />
              <site name="load_touch" type="box" pos="0.3714 -0.0990 -0.8442" size="0.0700 0.1170 0.0340" quat="0.9848 -0.0000 -0.1736 0.0000" rgba="0.8 0.2 .2 .4" />
              
              <joint axis="0.9397 0.0000 0.3420" name="ankle" pos="0.41473526863598564 -0.056023850890395646 -0.9436730025485469" range="-45.0000 90.0000" type="hinge" />
            </body>
          </body>
        </body>
      </body>
      <body name="rhipjoint" user="-0.0963 -0.0494 -0.0918" pos="-0.0 -0.0 0.0">
        <body name="rfemur" user="-0.2274 -0.0494 -0.4521" pos="-0.10921248665475912 -0.056023850890395646 -0.10410909942790122">
          <joint axis="0.0000 -1.0000 -0.0000" name="rfemur_z" pos="-0.10921248665475912 -0.056023850890395646 -0.10410909942790122" range="-70.0000 60.0000" type="hinge" />
          <joint axis="0.3420 -0.0000 0.9397" name="rfemur_y" pos="-0.10921248665475912 -0.056023850890395646 -0.10410909942790122" range="-70.0000 70.0000" type="hinge" />
          <joint axis="0.9397 0.0000 -0.3420" name="rfemur_x" pos="-0.10921248665475912 -0.056023850890395646 -0.10410909942790122" range="-160.0000 20.0000" type="hinge" />
          <geom fromto="-0.11692427179756662 -0.056023850890395646 -0.12542991717566312 -0.25017938272107854 -0.056023850890395646 -0.49139948564389546" size="0.0589724746214691" type="capsule" mass="10.8525" />
          <body name="rtibia" user="-0.3657 -0.0494 -0.8321" pos="-0.25789116786388605 -0.056023850890395646 -0.5127203033916573">
            <joint axis="0.9397 0.0000 -0.3420" name="rtibia_x" pos="-0.25789116786388605 -0.056023850890395646 -0.5127203033916573" range="0.0000 170.0000" type="hinge" />
            <geom contype="2" conaffinity="2" fromto="-0.26571636161173484 -0.056023850890395646 -0.5340411211394193 -0.4070234834931781 -0.056023850890395646 -0.9223521848007851" size="0.04196118386527609" type="capsule" mass="3.4274999999999998" />
            <body name="rfoot" user="-0.3731 -0.1606 -0.8523" pos="-0.41473526863598564 -0.056023850890395646 -0.9436730025485469">
              <geom contype="2" conaffinity="2" pos="-0.42119955912333895 -0.11227451899087387 -0.9573954437585426" size="0.06804516302477204 0.1213472073941768 0.027218065209908816" quat="0.9848 -0.0000 0.1736 -0.0000" type="box" mass="0.9974999999999999" />
              <joint axis="0.3420 -0.0000 0.9397" name="rfoot_z" pos="-0.41473526863598564 -0.056023850890395646 -0.9436730025485469" range="-20.0000 70.0000" type="hinge" />
              <joint axis="0.0000 -1.0000 0.0000" name="rfoot_y" pos="-0.41473526863598564 -0.056023850890395646 -0.9436730025485469" range="-45.0000 45.0000" type="hinge" />
              <joint axis="0.9397 -0.0000 -0.3420" name="rfoot_x" pos="-0.41473526863598564 -0.056023850890395646 -0.9436730025485469" range="-45.0000 90.0000" type="hinge" />
            </body>
          </body>
        </body>
      </body>
      <body name="lowerback" user="0.0006 0.0081 0.1132" pos="0.0 -0.0 0.0">
        <body name="upperback" user="0.0011 0.0071 0.2268" pos="0.0006804516302477203 0.009186097008344225 0.1283785409067366">
          <geom pos="0.0006804516302477203 0.009186097008344225 0.13971940141086525" size="0.07938602352890073" type="sphere" mass="3.9225" />
          <joint axis="0.0000 -1.0000 0.0000" name="upperback_z" pos="0.0006804516302477203 0.009186097008344225 0.1283785409067366" range="-30.0000 30.0000" type="hinge" />
          <joint axis="0.0000 -0.0000 1.0000" name="upperback_y" pos="0.0006804516302477203 0.009186097008344225 0.1283785409067366" range="-30.0000 30.0000" type="hinge" />
          <joint axis="1.0000 0.0000 0.0000" name="upperback_x" pos="0.0006804516302477203 0.009186097008344225 0.1283785409067366" range="-20.0000 45.0000" type="hinge" />
          <body name="thorax" user="0.0010 0.0024 0.3407" pos="0.001247494655454154 0.00805201095793136 0.25721071623363834">
            <geom pos="0.001247494655454154 0.00805201095793136 0.3184513629559331" size="0.11340860504128675" type="sphere" mass="11.617500000000001" />
            <body name="lowerneck" user="-0.0023 -0.0083 0.4312" pos="0.0011340860504128673 0.0027218065209908813 0.3863831173756639">
              <geom pos="-0.002608397915949595 -0.009412914218426799 0.620571886785921" size="0.09072688403302939" type="sphere" mass="5.1075" />
              <joint axis="0.0000 -1.0000 0.0000" name="lowerneck_z" pos="0.0011340860504128673 0.0027218065209908813 0.3863831173756639" range="-30.0000 30.0000" type="hinge" />
              <joint axis="0.0000 -0.0000 1.0000" name="lowerneck_y" pos="0.0011340860504128673 0.0027218065209908813 0.3863831173756639" range="-30.0000 30.0000" type="hinge" />
              <joint axis="1.0000 0.0000 0.0000" name="lowerneck_x" pos="0.0011340860504128673 0.0027218065209908813 0.3863831173756639" range="-20.0000 45.0000" type="hinge" />
              <body name="upperneck" user="-0.0013 -0.0038 0.5212" pos="-0.002608397915949595 -0.009412914218426799 0.48901790493802844">
                <body name="head" user="-0.0006 -0.0008 0.6176" pos="-0.0014743118655367274 -0.004309526991568896 0.5910856494751865">
                  <camera mode="fixed" xyaxes="-1 0 0 0 0 1" />
                </body>
              </body>
              <body name="lclavicle" user="0.1790 -0.0149 0.4121" pos="-0.002608397915949595 -0.009412914218426799 0.48901790493802844">
                <geom fromto="0.011454269109169959 -0.009979957243633233 0.4875435930724917 0.1889387359987837 -0.01633083912594529 0.46883117324067936" size="0.03855892571403749" type="capsule" mass="3.9225" />
                <joint axis="0.0000 -1.0000 0.0000" name="lclavicle_z" pos="0.0011340860504128673 0.0027218065209908813 0.3863831173756639" range="0.0000 20.0000" type="hinge" />
                <joint axis="0.0000 -0.0000 1.0000" name="lclavicle_y" pos="0.0011340860504128673 0.0027218065209908813 0.3863831173756639" range="-20.0000 10.0000" type="hinge" />
                <body name="lhumerus" user="0.4599 -0.0149 0.4121" pos="0.20300140302390324 -0.016897882151151723 0.46735686137514265">
                  <joint axis="-0.0000 0.8660 -0.5000" name="lhumerus_z" pos="0.20300140302390324 -0.016897882151151723 0.46735686137514265" range="-90.0000 90.0000" type="hinge" />
                  <joint axis="-1.0000 -0.0000 -0.0000" name="lhumerus_y" pos="0.20300140302390324 -0.016897882151151723 0.46735686137514265" range="-90.0000 90.0000" type="hinge" />
                  <joint axis="0.0000 -0.5000 -0.8660" name="lhumerus_x" pos="0.20300140302390324 -0.016897882151151723 0.46735686137514265" range="-60.0000 90.0000" type="hinge" />
                  <geom fromto="0.22284790890612843 -0.016897882151151723 0.46735686137514265 0.5017196687026525 -0.016897882151151723 0.46735686137514265" size="0.035156667562798886" type="capsule" mass="1.9725000000000001" />
                  <body name="lradius" user="0.6374 -0.0149 0.4121" pos="0.5215661745848776 -0.016897882151151723 0.46735686137514265">
                    <geom fromto="0.5215661745848776 -0.016897882151151723 0.46735686137514265 0.7228664485331616 -0.016897882151151723 0.46735686137514265" size="0.028352151260321687" type="capsule" mass="1.125" />
                    <joint axis="0.0000 -0.5000 -0.8660" name="lradius_x" pos="0.5215661745848776 -0.016897882151151723 0.46735686137514265" range="-10.0000 170.0000" type="hinge" />
                    <body name="lwrist" user="0.7261 -0.0149 0.4121" pos="0.7228664485331616 -0.016897882151151723 0.46735686137514265">
                      <geom pos="0.7727662347513278 -0.016897882151151723 0.46735686137514265" size="0.045363442016514696" type="sphere" mass="0.4425" />
                    </body>
                  </body>
                </body>
              </body>
              <body name="rclavicle" user="-0.1790 -0.0149 0.4121" pos="0.002608397915949595 -0.009412914218426799 0.48901790493802844">
                <geom fromto="-0.011454269109169959 -0.009979957243633233 0.4875435930724917 -0.1889387359987837 -0.01633083912594529 0.46883117324067936" size="0.03855892571403749" type="capsule" mass="3.9225" />
                <joint axis="0.0000 -1.0000 0.0000" name="rclavicle_z" pos="-0.0011340860504128673 0.0027218065209908813 0.3863831173756639" range="-20.0000 0.0000" type="hinge" />
                <joint axis="0.0000 -0.0000 1.0000" name="rclavicle_y" pos="-0.0011340860504128673 0.0027218065209908813 0.3863831173756639" range="-10.0000 20.0000" type="hinge" />
                <body name="rhumerus" user="-0.4599 -0.0149 0.4121" pos="-0.20300140302390324 -0.016897882151151723 0.46735686137514265">
                  <joint axis="0.0000 0.8660 -0.5000" name="rhumerus_z" pos="-0.20300140302390324 -0.016897882151151723 0.46735686137514265" range="-90.0000 90.0000" type="hinge" />
                  <joint axis="1.0000 -0.0000 -0.0000" name="rhumerus_y" pos="-0.20300140302390324 -0.016897882151151723 0.46735686137514265" range="-90.0000 90.0000" type="hinge" />
                  <joint axis="0.0000 0.5000 0.8660" name="rhumerus_x" pos="-0.20300140302390324 -0.016897882151151723 0.46735686137514265" range="-90.0000 60.0000" type="hinge" />
                  <geom fromto="-0.22284790890612843 -0.016897882151151723 0.46735686137514265 -0.5017196687026525 -0.016897882151151723 0.46735686137514265" size="0.035156667562798886" type="capsule" mass="1.9725000000000001" />
                  <body name="rradius" user="-0.6374 -0.0149 0.4121" pos="-0.5215661745848776 -0.016897882151151723 0.46735686137514265">
                    <geom fromto="-0.5215661745848776 -0.016897882151151723 0.46735686137514265 -0.7228664485331616 -0.016897882151151723 0.46735686137514265" size="0.028352151260321687" type="capsule" mass="1.125" />
                    <joint axis="0.0000 0.5000 0.8660" name="rradius_x" pos="-0.5215661745848776 -0.016897882151151723 0.46735686137514265" range="-10.0000 170.0000" type="hinge" />
                    <body name="rwrist" user="-0.7261 -0.0149 0.4121" pos="-0.7228664485331616 -0.016897882151151723 0.46735686137514265">
                      <geom pos="-0.7727662347513278 -0.016897882151151723 0.46735686137514265" size="0.045363442016514696" type="sphere" mass="0.4425" />
                    </body>
                  </body>
                </body>
              </body>
            </body>
          </body>
        </body>
      </body>
    </body>
  </worldbody>
  <sensor>
    <force name="lforce" site="load_force" />
  </sensor>
  <sensor>
    <touch name="ltouch" site="load_touch" /> 
  </sensor>
  <actuator>
    <motor gear="1" joint="lfemur_z" name="lfemur_z" />
    <motor gear="1" joint="lfemur_y" name="lfemur_y" />
    <motor gear="1" joint="lfemur_x" name="lfemur_x" />
    <motor gear="1" joint="knee" name="knee" />
    
    <motor gear="1" joint="ankle" name="ankle" />
    <motor gear="1" joint="rfemur_z" name="rfemur_z" />
    <motor gear="1" joint="rfemur_y" name="rfemur_y" />
    <motor gear="1" joint="rfemur_x" name="rfemur_x" />
    <motor gear="1" joint="rtibia_x" name="rtibia_x" />
    <motor gear="1" joint="rfoot_z" name="rfoot_z" />
    <motor gear="1" joint="rfoot_y" name="rfoot_y" />
    <motor gear="1" joint="rfoot_x" name="rfoot_x" />
    <motor gear="1" joint="upperback_z" name="upperback_z" />
    <motor gear="1" joint="upperback_y" name="upperback_y" />
    <motor gear="1" joint="upperback_x" name="upperback_x" />
    <motor gear="1" joint="lowerneck_z" name="lowerneck_z" />
    <motor gear="1" joint="lowerneck_y" name="lowerneck_y" />
    <motor gear="1" joint="lowerneck_x" name="lowerneck_x" />
    <motor gear="1" joint="lclavicle_z" name="lclavicle_z" />
    <motor gear="1" joint="lclavicle_y" name="lclavicle_y" />
    <motor gear="1" joint="lhumerus_z" name="lhumerus_z" />
    <motor gear="1" joint="lhumerus_y" name="lhumerus_y" />
    <motor gear="1" joint="lhumerus_x" name="lhumerus_x" />
    <motor gear="1" joint="lradius_x" name="lradius_x" />
    <motor gear="1" joint="rclavicle_z" name="rclavicle_z" />
    <motor gear="1" joint="rclavicle_y" name="rclavicle_y" />
    <motor gear="1" joint="rhumerus_z" name="rhumerus_z" />
    <motor gear="1" joint="rhumerus_y" name="rhumerus_y" />
    <motor gear="1" joint="rhumerus_x" name="rhumerus_x" />
    <motor gear="1" joint="rradius_x" name="rradius_x" />
  </actuator>
</mujoco>