<mujoco model="humanoid">
  <compiler angle="degree" inertiafromgeom="true" coordinate="global"/>
  <include file="./common/materials.xml"/>
    <visual>
    <headlight ambient=".4 .4 .4" diffuse=".8 .8 .8" specular="0.3 0.3 0.3"/>
    <map znear=".01"/>
    <quality shadowsize="2048"/>
  </visual>
  <default>
    <joint damping="0.0" armature="0.01" stiffness="0.0" limited="true"/>
    <geom conaffinity="7" condim="1" contype="7" margin="0.001" material="self" rgba=".98 .54 .56 1."/>
  </default>
  <statistic extent="3" center="0 0 1"/>
  <option timestep="0.00222222222"/>
  <asset>
    <texture type="skybox" file="./common/sky1.png" gridsize="3 4" gridlayout=".U..LFRB.D.." width="8192" height="8192"/>
    <texture builtin="flat" height="1278" mark="cross" markrgb="1 1 1" name="texgeom" random="0.01" rgb1=".8 .6 .4" rgb2=".8 .6 .4" type="cube" width="127"/>
  </asset>
  <worldbody>
    <light cutoff="100" diffuse="1 1 1" dir="-0 0 -1.3" directional="true" exponent="1" pos="0 0 1.3" specular=".1 .1 .1"/>
    <geom condim="3" friction="1. .1 .1" material="grid_new" name="floor" pos="0 0 -1.3" rgba=".8 .9 .8 1" size="100 100 .2" type="plane"/>
    <!-- <geom condim="3" friction="1. .1 .1" material="grid_new" name="floor" pos="0 0 0" rgba=".8 .9 .8 1" size="100 100 .2" type="plane" euler="0 0 0"/> -->
    <body name="root" user="0.0000 -0.0000 0.0000" pos="0.0000 -0.0000 0.0000">
      <joint armature="0.0" limited="false" name="root" pos="0.0000 -0.0000 0.0000"  type="hinge"/>
      <geom pos="0.0000 0.0000 -0.0240" size="0.1100" type="sphere"/>
      <body name="lhipjoint" user="0.0963 -0.0494 -0.0918" pos="0.0000 -0.0000 0.0000">
        <body name="lfemur" user="0.2274 -0.0494 -0.4521" pos="0.0963 -0.0494 -0.0918">
          <joint axis="0.0000 -1.0000 0.0000" name="lfemur_z" pos="0.0963 -0.0494 -0.0918" range="-60.0000 70.0000" type="hinge"/>
          <joint axis="-0.3420 -0.0000 0.9397" name="lfemur_y" pos="0.0963 -0.0494 -0.0918" range="-70.0000 70.0000" type="hinge"/>
          <joint axis="0.9397 0.0000 0.3420" name="lfemur_x" pos="0.0963 -0.0494 -0.0918" range="-160.0000 20.0000" type="hinge"/>
          <geom fromto="0.1031 -0.0494 -0.1106 0.2206 -0.0494 -0.4333" size="0.0520" type="capsule"/>
          <body name="ltibia" user="0.3657 -0.0494 -0.8321" pos="0.2274 -0.0494 -0.4521">
            <joint axis="0.9397 0.0000 0.3420" name="ltibia_x" stiffness="1e3" pos="0.2274 -0.0494 -0.4521" range="0.0000 170.0000" type="hinge"/>
            <geom contype="1" conaffinity="1" fromto="0.2343 -0.0494 -0.4709 0.3589 -0.0494 -0.8133" size="0.0370" type="capsule"/>
            <body name="lfoot" user="0.3731 -0.1606 -0.8523" pos="0.3657 -0.0494 -0.8321">
              <geom contype="1" conaffinity="1" pos="0.3714 -0.0990 -0.8442" size="0.0600 0.1070 0.0240" quat="0.9848 -0.0000 -0.1736 0.0000" type="box"/>
              <joint axis="-0.3420 -0.0000 0.9397" name="lfoot_z" stiffness= "1e3" pos="0.3657 -0.0494 -0.8321" range="-70.0000 20.0000" type="hinge"/>
              <joint axis="0.0000 -1.0000 0.0000" name="lfoot_y" stiffness= "1e3" pos="0.3657 -0.0494 -0.8321" range="-45.0000 45.0000" type="hinge"/>
              <joint axis="0.9397 0.0000 0.3420" name="lfoot_x" pos="0.3657 -0.0494 -0.8321" range="-45.0000 90.0000" type="hinge"/>
            </body>
          </body>
        </body>
      </body>
    </body>
  </worldbody>
  <actuator>
    <motor gear="100" joint="lfemur_z" name="lfemur_z"/> 
    <motor gear="100" joint="lfemur_y" name="lfemur_y"/>
    <motor gear="100" joint="lfemur_x" name="lfemur_x"/>
    <motor gear="100" joint="ltibia_x" name="ltibia_x"/>
    <motor gear="100" joint="lfoot_z" name="lfoot_z"/>
    <motor gear="100" joint="lfoot_y" name="lfoot_y"/>
    <motor gear="100" joint="lfoot_x" name="lfoot_x"/>
  </actuator>
</mujoco>
