<mujoco model="humanoid">

  <include file="./common/skybox.xml" />
  <include file="./common/visual.xml" />
  <include file="./common/materials.xml" />

  <statistic extent="2" center="0 0 1" />

  <default class="main">
    <joint limited="true" solimplimit="0 0.99 0.01" stiffness="0.1" armature=".01" damping="1" />
    <geom friction="0.7" solref="0.015 1" solimp="0.95 0.99 0.003" />
    <motor ctrllimited="true" ctrlrange="-1 1" />
    <default class="humanoid">
      <geom type="capsule" material="self" />
      <default class="stiff_low">
        <joint stiffness=".5" damping="4" />
      </default>
      <default class="stiff_medium">
        <joint stiffness="10" damping="5" />
      </default>
      <default class="stiff_high">
        <joint stiffness="30" damping="10" />
      </default>
      <default class="touch">
        <site group="3" rgba="0 0 1 .5" />
      </default>
    </default>
  </default>

  <worldbody>
    <geom name="floor" type="plane" conaffinity="1" size="102.07957998604313 102.07957998604313 0.20415915997208628" material="grid" />
    <light name="tracking_light" pos="0 0 7" dir="0 0 -1" mode="trackcom" />
    <camera name="back" pos="0 3 2.4" xyaxes="-1 0 0 0 -1 2" mode="trackcom" />
    <camera name="side" pos="-3 0 2.4" xyaxes="0 -1 0 1 0 2" mode="trackcom" />
    <body name="root" childclass="humanoid" pos="0.0 0.0 1.0207957998604313" euler="90 0 0">
      
      <freejoint name="root" />
      <geom name="root_geom" size="0.09187162198743881 0.06124774799162588" pos="0.0 -0.05103978999302157 0.0" quat="1 0 -1 0" />
      <body name="lhipjoint" pos="0.0 0.0 0.0">
        <geom name="lhipjoint" size="0.00816636639888345 0.022457507596929487" pos="0.052060585792881996 -0.04695660679357984 0.025519894996510785" quat="0.5708 -0.566602 -0.594264 0" />
        <body name="lfemur" pos="0.10412117158576399 -0.09391321358715968 0.05103978999302157" quat="1 0 0 0.17365">
          <joint name="lfemur_z" axis="0 0 1" range="-60 70" class="stiff_medium" pos="0.0 0.0 0.0" />
          <joint name="lfemur_y" axis="0 1 0" range="-70 70" class="stiff_medium" pos="0.0 0.0 0.0" />
          <joint name="lfemur_x" axis="1 0 0" range="-160 20" class="stiff_medium" pos="0.0 0.0 0.0" />
          <geom name="lfemur" size="0.06124774799162588 0.17353528597627335" pos="-0.010207957998604314 -0.2066835879851411 0.0" quat="0.7 -0.7 -0.1228 -0.07" />
          <body name="ltibia" pos="0.0 -0.4133661551744824 0.0">
            <joint name="ltibia_x" axis="1 0 0" range="1   170" class="stiff_low" pos="0.0 0.0 0.0" />
            <geom name="ltibia" size="0.03062387399581294 0.18635791033664018" pos="0.0 -0.20706434481848907 0.0" quat="0.7 -0.7 -0.1228 -0.1228" />
            <geom name="lcalf" size="0.045935810993719406 0.08166366398883451" pos="0.0 -0.10207957998604314 -0.010207957998604314" quat="0.7 -0.7 -0.1228 -0.1228" />
            <body name="lfoot" pos="0.0 -0.414129710432778 0.0" quat="0.707107 -0.707107 0 0">
              
              <joint name="lfoot_z" axis="0 0 1" range="-70 20" class="stiff_medium" pos="0.0 0.0 0.0" />
              <joint name="lfoot_x" axis="1 0 0" range="-45    90" class="stiff_medium" pos="0.0 0.0 0.0" />
              <geom name="lfoot0" size="0.020415915997208628 0.06124774799162588" pos="-0.020415915997208628 -0.02347830339678992 -0.010207957998604314" euler="100 -2 0" />
              <geom name="lfoot1" size="0.020415915997208628 0.06124774799162588" pos="0.0 -0.02347830339678992 -0.010207957998604314" euler="100 0 0" />
              <geom name="lfoot2" size="0.020415915997208628 0.06124774799162588" pos="0.010207957998604314 -0.02347830339678992 -0.010207957998604314" euler="100 10 0" />
              <body name="ltoes" pos="0.0 -0.1085840908227538 -0.02324923681930124">
                <joint name="ltoes_x" axis="1 0 0" range="-90 20" pos="0.0 0.0 0.0" />
                <geom name="ltoes0" type="sphere" size="0.020415915997208628" pos="-0.025519894996510785 -0.010207957998604314 -0.010207957998604314" />
                <geom name="ltoes1" type="sphere" size="0.020415915997208628" pos="0.0 -0.005103978999302157 -0.010207957998604314" />
                <geom name="ltoes2" type="sphere" size="0.020415915997208628" pos="0.020415915997208628 0.0010207957998604313 -0.010207957998604314" />
                
              </body>
            </body>
          </body>
        </body>
      </body>
      <body name="rhipjoint" pos="0.0 0.0 0.0">
        <geom name="rhipjoint" size="0.00816636639888345 0.022457507596929487" pos="-0.052060585792881996 -0.04695660679357984 0.025519894996510785" quat="0.574856 -0.547594 0.608014 0" />
        <body name="rfemur" pos="-0.10412117158576399 -0.09391321358715968 0.05103978999302157" quat="1 0 0 -0.17365">
          <joint name="rfemur_z" axis="0 0 1" range="-70 60" class="stiff_medium" pos="0.0 0.0 0.0" />
          <joint name="rfemur_y" axis="0 1 0" range="-70 70" class="stiff_medium" pos="0.0 0.0 0.0" />
          <joint name="rfemur_x" axis="1 0 0" range="-160 20" class="stiff_medium" pos="0.0 0.0 0.0" />
          <geom name="rfemur" size="0.06124774799162588 0.17353528597627335" pos="0.010207957998604314 -0.2066835879851411 0.0" quat="0.7 -0.7 0.1228 0.07" />
          <body name="rtibia" pos="0.0 -0.4133661551744824 0.0">
            <joint name="rtibia_x" axis="1 0 0" range="1   170" class="stiff_low" pos="0.0 0.0 0.0" />
            <geom name="rtibia" size="0.03062387399581294 0.18635791033664018" pos="0.0 -0.20706434481848907 0.0" quat="0.7 -0.7 0.1228 0.1228" />
            <geom name="rcalf" size="0.045935810993719406 0.08166366398883451" pos="0.0 -0.10207957998604314 -0.010207957998604314" quat="0.7 -0.7 -0.1228 -0.1228" />
            <body name="rfoot" pos="0.0 -0.414129710432778 0.0" quat="0.707107 -0.707107 0 0">
              
              <joint name="rfoot_z" axis="0 0 1" range="-20 70" class="stiff_medium" pos="0.0 0.0 0.0" />
              <joint name="rfoot_x" axis="1 0 0" range="-45    90" class="stiff_medium" pos="0.0 0.0 0.0" />
              <geom name="rfoot0" size="0.020415915997208628 0.06124774799162588" pos="0.020415915997208628 -0.02347830339678992 -0.010207957998604314" euler="100 2 0" />
              <geom name="rfoot1" size="0.020415915997208628 0.06124774799162588" pos="0.0 -0.02347830339678992 -0.010207957998604314" euler="100 0 0" />
              <geom name="rfoot2" size="0.020415915997208628 0.06124774799162588" pos="-0.010207957998604314 -0.02347830339678992 -0.010207957998604314" euler="100 -10 0" />
              <body name="rtoes" pos="0.0 -0.1085840908227538 -0.02324923681930124">
                <joint name="rtoes_x" axis="1 0 0" range="-90 20" pos="0.0 0.0 0.0" />
                <geom name="rtoes0" type="sphere" size="0.020415915997208628" pos="0.025519894996510785 -0.010207957998604314 -0.010207957998604314" />
                <geom name="rtoes1" type="sphere" size="0.020415915997208628" pos="0.0 -0.005103978999302157 -0.010207957998604314" />
                <geom name="rtoes2" type="sphere" size="0.020415915997208628" pos="-0.020415915997208628 0.0010207957998604313 -0.010207957998604314" />
                
              </body>
            </body>
          </body>
        </body>
      </body>
      <body name="lowerback" pos="0.0 0.0 0.0">
        <joint name="lowerback_z" axis="0 0 1" range="-30 30" class="stiff_high" pos="0.0 0.0 0.0" />
        <joint name="lowerback_y" axis="0 1 0" range="-30 30" class="stiff_high" pos="0.0 0.0 0.0" />
        <joint name="lowerback_x" axis="1 0 0" range="-20 45" class="stiff_high" pos="0.0 0.0 0.0" />
        <geom name="lowerback" size="0.06635172699092803 0.05614376899232373" pos="0.0 0.05716456479218416 0.03062387399581294" quat="1 0 1 0" />
        <body name="upperback" pos="0.0 0.10207957998604314 -0.010207957998604314">
          <joint name="upperback_z" axis="0 0 1" range="-30 30" class="stiff_high" pos="0.0 0.0 0.0" />
          <joint name="upperback_y" axis="0 1 0" range="-30 30" class="stiff_high" pos="0.0 0.0 0.0" />
          <joint name="upperback_x" axis="1 0 0" range="-20 45" class="stiff_high" pos="0.0 0.0 0.0" />
          <geom name="upperback" size="0.06124774799162588 0.06124774799162588" pos="0.0 0.06124774799162588 0.020415915997208628" quat="1 0 1 0" />
          <body name="thorax" pos="0.0005231864297108672 0.11592157103215057 0.0009563029420210492">
            <joint name="thorax_z" axis="0 0 1" range="-30 30" class="stiff_high" pos="0.0 0.0 0.0" />
            <joint name="thorax_y" axis="0 1 0" range="-30 30" class="stiff_high" pos="0.0 0.0 0.0" />
            <joint name="thorax_x" axis="1 0 0" range="-20 45" class="stiff_high" pos="0.0 0.0 0.0" />
            <geom name="thorax" size="0.08166366398883451 0.0714557059902302" pos="0.0 0.05103978999302157 0.0" quat="1 0 1 0" />
            <body name="lowerneck" pos="0.0 0.11631457741509685 0.004777702037792766">
              <joint name="lowerneck_z" axis="0 0 1" range="-30 30" class="stiff_medium" pos="0.0 0.0 0.0" />
              <joint name="lowerneck_y" axis="0 1 0" range="-30 30" class="stiff_medium" pos="0.0 0.0 0.0" />
              <joint name="lowerneck_x" axis="1 0 0" range="-20 45" class="stiff_medium" pos="0.0 0.0 0.0" />
              <geom name="lowerneck" size="0.08166366398883451 0.020415915997208628" pos="0.0 0.040831831994417256 -0.020415915997208628" quat="1 1 0 0" />
              <body name="upperneck" pos="0.0 0.09187162198743881 0.010207957998604314">
                <joint name="upperneck_z" axis="0 0 1" range="-30 30" class="stiff_medium" pos="0.0 0.0 0.0" />
                <joint name="upperneck_y" axis="0 1 0" range="-30 30" class="stiff_medium" pos="0.0 0.0 0.0" />
                <joint name="upperneck_x" axis="1 0 0" range="-20 45" class="stiff_medium" pos="0.0 0.0 0.0" />
                <geom name="upperneck" size="0.05103978999302157 0.03062387399581294" pos="0.0 0.05103978999302157 0.0" quat=".8 1 0 0" />
                <body name="head" pos="0.0 0.09187162198743881 0.0">
                  <camera name="egocentric" pos="0 0 0" xyaxes="-1 0 0 0 1 0" fovy="80" />
                  <joint name="head_z" axis="0 0 1" range="-30 30" class="stiff_medium" pos="0.0 0.0 0.0" />
                  <joint name="head_y" axis="0 1 0" range="-30 30" class="stiff_medium" pos="0.0 0.0 0.0" />
                  <joint name="head_x" axis="1 0 0" range="-20 45" class="stiff_medium" pos="0.0 0.0 0.0" />
                  <geom name="head" size="0.08676764298813668 0.0357278529951151" pos="0.0 0.11228753798464745 0.03062387399581294" quat="1 .9 0 0" />
                  <geom name="leye" type="sphere" size="0.020415915997208628" pos="0.03062387399581294 0.11228753798464745 0.10207957998604314" />
                  <geom name="reye" type="sphere" size="0.020415915997208628" pos="-0.03062387399581294 0.11228753798464745 0.10207957998604314" />
                </body>
              </body>
            </body>
            <body name="lclavicle" pos="0.0 0.11631457741509685 0.004777702037792766">
              <joint name="lclavicle_z" axis="0 0 1" range="0 20" class="stiff_high" pos="0.0 0.0 0.0" />
              <joint name="lclavicle_y" axis="0 1 0" range="-20 10" class="stiff_high" pos="0.0 0.0 0.0" />
              <geom name="lclavicle" size="0.08166366398883451 0.040831831994417256" pos="0.09187162198743881 0.05103978999302157 -0.010207957998604314" quat="1 0 -1 -.4" />
              <body name="lhumerus" pos="0.18680563137445894 0.07758048078939278 0.010207957998604314" quat="0.18 0.68 -0.68 0.18">
                <joint name="lhumerus_z" axis="0 0 1" range="-90 90" class="stiff_low" pos="0.0 0.0 0.0" />
                <joint name="lhumerus_y" axis="0 1 0" range="-90 90" class="stiff_low" pos="0.0 0.0 0.0" />
                <joint name="lhumerus_x" axis="1 0 0" range="-60 90" class="stiff_low" pos="0.0 0.0 0.0" />
                <geom name="lhumerus" size="0.0357278529951151 0.1265786791826935" pos="0.0 -0.14086982038073953 0.0" quat="0.612 -0.612 0.35 0.35" />
                <body name="lradius" pos="0.0 -0.2827604365613395 0.0">
                  <joint name="lradius_x" axis="1 0 0" range="-10 170" class="stiff_low" pos="0.0 0.0 0.0" />
                  <geom name="lradius" size="0.03062387399581294 0.06124774799162588" pos="0.0 -0.08166366398883451 0.0" quat="0.612 -0.612 0.35 0.35" />
                  <body name="lwrist" pos="0.0 -0.17353528597627335 0.0" quat="-0.5 0 0.866 0">
                    <joint name="lwrist_y" axis="0 1 0" range="-180 0" pos="0.0 0.0 0.0" />
                    <geom name="lwrist" size="0.025519894996510785 0.03062387399581294" pos="0.0 -0.020415915997208628 0.0" quat="0 0 -1 -1" />
                    <body name="lhand" pos="0.0 -0.08166366398883451 0.0">
                      <joint name="lhand_z" axis="0 0 1" range="-45 45" pos="0.0 0.0 0.0" />
                      <joint name="lhand_x" axis="1 0 0" range="-90 90" pos="0.0 0.0 0.0" />
                      <geom name="lhand" type="ellipsoid" size="0.048998198393300704 0.020415915997208628 0.06124774799162588" pos="0.0 -0.04797740259344027 0.0" quat="0 0 -1 -1" />
                      <body name="lfingers" pos="0.0 -0.08166366398883451 0.0">
                        <joint name="lfingers_x" axis="1 0 0" range="0 90" pos="0.0 0.0 0.0" />
                        <geom name="lfinger0" size="0.010207957998604314 0.040831831994417256" pos="-0.03062387399581294 -0.05103978999302157 0.0" quat="1 -1 0 0" />
                        <geom name="lfinger1" size="0.010207957998604314 0.040831831994417256" pos="-0.00816636639888345 -0.06124774799162588 0.0" quat="1 -1 0 0" />
                        <geom name="lfinger2" size="0.009187162198743881 0.040831831994417256" pos="0.01429114119804604 -0.06124774799162588 0.0" quat="1 -1 0 0" />
                        <geom name="lfinger3" size="0.00816636639888345 0.040831831994417256" pos="0.0326654655955338 -0.05103978999302157 0.0" quat="1 -1 0 0" />
                      </body>
                      <body name="lthumb" pos="-0.020415915997208628 -0.03062387399581294 0.0" quat="0.92388 0 0 -0.382683">
                        <joint name="lthumb_z" axis="0 0 1" range="-45 45" pos="0.0 0.0 0.0" />
                        <joint name="lthumb_x" axis="1 0 0" range="0 90" pos="0.0 0.0 0.0" />
                        <geom name="lthumb" size="0.012249549598325176 0.040831831994417256" pos="0.0 -0.06124774799162588 0.0" quat="0 0 -1 -1" />
                      </body>
                    </body>
                  </body>
                </body>
              </body>
            </body>
            <body name="rclavicle" pos="0.0 0.11631457741509685 0.004777702037792766">
              <joint name="rclavicle_z" axis="0 0 1" range="-20 0" class="stiff_high" pos="0.0 0.0 0.0" />
              <joint name="rclavicle_y" axis="0 1 0" range="-10 20" class="stiff_high" pos="0.0 0.0 0.0" />
              <geom name="rclavicle" size="0.08166366398883451 0.040831831994417256" pos="-0.09187162198743881 0.05103978999302157 -0.010207957998604314" quat="1 0 -1 .4" />
              <body name="rhumerus" pos="-0.18680563137445894 0.07758048078939278 0.010207957998604314" quat="0.18 0.68 0.68 -0.18">
                <joint name="rhumerus_z" axis="0 0 1" range="-90 90" class="stiff_low" pos="0.0 0.0 0.0" />
                <joint name="rhumerus_y" axis="0 1 0" range="-90 90" class="stiff_low" pos="0.0 0.0 0.0" />
                <joint name="rhumerus_x" axis="1 0 0" range="-60 90" class="stiff_low" pos="0.0 0.0 0.0" />
                <geom name="rhumerus" size="0.0357278529951151 0.1265786791826935" pos="0.0 -0.14086982038073953 0.0" quat="0.61 -0.61 -0.35 -0.35" />
                <body name="rradius" pos="0.0 -0.2827604365613395 0.0">
                  <joint name="rradius_x" axis="1 0 0" range="-10 170" class="stiff_low" pos="0.0 0.0 0.0" />
                  <geom name="rradius" size="0.03062387399581294 0.06124774799162588" pos="0.0 -0.08166366398883451 0.0" quat="0.612 -0.612 -0.35 -0.35" />
                  <body name="rwrist" pos="0.0 -0.17353528597627335 0.0" quat="-0.5 0 -0.866 0">
                    <joint name="rwrist_y" axis="0 1 0" range="-180 0" pos="0.0 0.0 0.0" />
                    <geom name="rwrist" size="0.025519894996510785 0.03062387399581294" pos="0.0 -0.020415915997208628 0.0" quat="0 0 1 1" />
                    <body name="rhand" pos="0.0 -0.08166366398883451 0.0">
                      <joint name="rhand_z" axis="0 0 1" range="-45 45" pos="0.0 0.0 0.0" />
                      <joint name="rhand_x" axis="1 0 0" range="-90 90" pos="0.0 0.0 0.0" />
                      <geom name="rhand" type="ellipsoid" size="0.048998198393300704 0.020415915997208628 0.06124774799162588" pos="0.0 -0.04797740259344027 0.0" quat="0 0 1 1" />
                      <body name="rfingers" pos="0.0 -0.08166366398883451 0.0">
                        <joint name="rfingers_x" axis="1 0 0" range="0 90" pos="0.0 0.0 0.0" />
                        <geom name="rfinger0" size="0.010207957998604314 0.040831831994417256" pos="0.03062387399581294 -0.05103978999302157 0.0" quat="1 -1  0 0" />
                        <geom name="rfinger1" size="0.010207957998604314 0.040831831994417256" pos="0.00816636639888345 -0.06124774799162588 0.0" quat="1 -1  0 0" />
                        <geom name="rfinger2" size="0.009187162198743881 0.040831831994417256" pos="-0.01429114119804604 -0.06124774799162588 0.0" quat="1 -1  0 0" />
                        <geom name="rfinger3" size="0.00816636639888345 0.040831831994417256" pos="-0.0326654655955338 -0.05103978999302157 0.0" quat="1 -1  0 0" />
                      </body>
                      <body name="rthumb" pos="0.020415915997208628 -0.03062387399581294 0.0" quat="0.92388 0 0 0.382683">
                        <joint name="rthumb_z" axis="0 0 1" range="-45    45" pos="0.0 0.0 0.0" />
                        <joint name="rthumb_x" axis="1 0 0" range="0 90" pos="0.0 0.0 0.0" />
                        <geom name="rthumb" size="0.012249549598325176 0.040831831994417256" pos="0.0 -0.06124774799162588 0.0" quat="0 0 1 1" />
                      </body>
                    </body>
                  </body>
                </body>
              </body>
            </body>
          </body>
        </body>
      </body>
    </body>
  </worldbody>

  <contact>
    <exclude body1="lclavicle" body2="rclavicle" />
    <exclude body1="lowerneck" body2="lclavicle" />
    <exclude body1="lowerneck" body2="rclavicle" />
    <exclude body1="upperneck" body2="lclavicle" />
    <exclude body1="upperneck" body2="rclavicle" />
  </contact>

  <actuator>
    <motor name="head_x" joint="head_x" gear="20" />
    <motor name="head_y" joint="head_y" gear="20" />
    <motor name="head_z" joint="head_z" gear="20" />
    <motor name="lclavicle_y" joint="lclavicle_y" gear="20" />
    <motor name="lclavicle_z" joint="lclavicle_z" gear="20" />
    <motor name="lfemur_x" joint="lfemur_x" gear="120" />
    <motor name="lfemur_y" joint="lfemur_y" gear="40" />
    <motor name="lfemur_z" joint="lfemur_z" gear="40" />
    <motor name="lfingers_x" joint="lfingers_x" gear="20" />
    <motor name="lfoot_x" joint="lfoot_x" gear="20" />
    <motor name="lfoot_z" joint="lfoot_z" gear="20" />
    <motor name="lhand_x" joint="lhand_x" gear="20" />
    <motor name="lhand_z" joint="lhand_z" gear="20" />
    <motor name="lhumerus_x" joint="lhumerus_x" gear="40" />
    <motor name="lhumerus_y" joint="lhumerus_y" gear="40" />
    <motor name="lhumerus_z" joint="lhumerus_z" gear="40" />
    <motor name="lowerback_x" joint="lowerback_x" gear="40" />
    <motor name="lowerback_y" joint="lowerback_y" gear="40" />
    <motor name="lowerback_z" joint="lowerback_z" gear="40" />
    <motor name="lowerneck_x" joint="lowerneck_x" gear="20" />
    <motor name="lowerneck_y" joint="lowerneck_y" gear="20" />
    <motor name="lowerneck_z" joint="lowerneck_z" gear="20" />
    <motor name="lradius_x" joint="lradius_x" gear="40" />
    <motor name="lthumb_x" joint="lthumb_x" gear="20" />
    <motor name="lthumb_z" joint="lthumb_z" gear="20" />
    <motor name="ltibia_x" joint="ltibia_x" gear="80" />
    <motor name="ltoes_x" joint="ltoes_x" gear="20" />
    <motor name="lwrist_y" joint="lwrist_y" gear="20" />
    <motor name="rclavicle_y" joint="rclavicle_y" gear="20" />
    <motor name="rclavicle_z" joint="rclavicle_z" gear="20" />
    <motor name="rfemur_x" joint="rfemur_x" gear="120" />
    <motor name="rfemur_y" joint="rfemur_y" gear="40" />
    <motor name="rfemur_z" joint="rfemur_z" gear="40" />
    <motor name="rfingers_x" joint="rfingers_x" gear="20" />
    <motor name="rfoot_x" joint="rfoot_x" gear="20" />
    <motor name="rfoot_z" joint="rfoot_z" gear="20" />
    <motor name="rhand_x" joint="rhand_x" gear="20" />
    <motor name="rhand_z" joint="rhand_z" gear="20" />
    <motor name="rhumerus_x" joint="rhumerus_x" gear="40" />
    <motor name="rhumerus_y" joint="rhumerus_y" gear="40" />
    <motor name="rhumerus_z" joint="rhumerus_z" gear="40" />
    <motor name="rradius_x" joint="rradius_x" gear="40" />
    <motor name="rthumb_x" joint="rthumb_x" gear="20" />
    <motor name="rthumb_z" joint="rthumb_z" gear="20" />
    <motor name="rtibia_x" joint="rtibia_x" gear="80" />
    <motor name="rtoes_x" joint="rtoes_x" gear="20" />
    <motor name="rwrist_y" joint="rwrist_y" gear="20" />
    <motor name="thorax_x" joint="thorax_x" gear="40" />
    <motor name="thorax_y" joint="thorax_y" gear="40" />
    <motor name="thorax_z" joint="thorax_z" gear="40" />
    <motor name="upperback_x" joint="upperback_x" gear="40" />
    <motor name="upperback_y" joint="upperback_y" gear="40" />
    <motor name="upperback_z" joint="upperback_z" gear="40" />
    <motor name="upperneck_x" joint="upperneck_x" gear="20" />
    <motor name="upperneck_y" joint="upperneck_y" gear="20" />
    <motor name="upperneck_z" joint="upperneck_z" gear="20" />
  </actuator>

  <sensor>
    <subtreelinvel name="thorax_subtreelinvel" body="thorax" />
    
  </sensor>

</mujoco>