<mujoco model="humanoid">

  <include file="./common/skybox.xml"/>
  <include file="./common/visual.xml"/>
  <include file="./common/materials.xml"/>

  <statistic extent="2" center="0 0 1"/>

  <default class="main">
    <joint limited="true" solimplimit="0 0.99 0.01" stiffness="0.1" armature=".01" damping="1"/>
    <geom friction="0.7" solref="0.015 1" solimp="0.95 0.99 0.003"/>
    <motor ctrllimited="true" ctrlrange="-1 1"/>
    <default class="humanoid">
      <geom type="capsule" material="self"/>
      <default class="stiff_low">
        <joint stiffness=".5" damping="4"/>
      </default>
      <default class="stiff_medium">
        <joint stiffness="10" damping="5"/>
      </default>
      <default class="stiff_high">
        <joint stiffness="30" damping="10"/>
      </default>
      <default class="touch">
        <site group="3" rgba="0 0 1 .5"/>
      </default>
    </default>
  </default>

  <worldbody>
    <geom name="floor" type="plane" conaffinity="1" size="100 100 .2" material="grid"/>
    <light name="tracking_light" pos="0 0 7" dir="0 0 -1" mode="trackcom"/>
    <camera name="back" pos="0 3 2.4" xyaxes="-1 0 0 0 -1 2" mode="trackcom"/>
    <camera name="side" pos="-3 0 2.4" xyaxes="0 -1 0 1 0 2" mode="trackcom"/>
    <body name="root" childclass="humanoid" pos="0 0 1" euler="90 0 0">
      <!-- <site name="root" size=".01" rgba="0.5 0.5 0.5 0"/> -->
      <freejoint name="root"/>
      <geom name="root_geom" size="0.09 0.06" pos="0 -0.05 0" quat="1 0 -1 0"/>
      <body name="lhipjoint" pos = "0 0 0">
        <geom name="lhipjoint" size="0.008 0.022" pos="0.051 -0.046 0.025" quat="0.5708 -0.566602 -0.594264 0"/>
        <body name="lfemur" pos="0.102 -0.092 0.05" quat="1 0 0 0.17365">
          <joint name="lfemur_z" axis="0 0 1" range="-60 70" class="stiff_medium"/>
          <joint name="lfemur_y" axis="0 1 0" range="-70 70" class="stiff_medium"/>
          <joint name="lfemur_x" axis="1 0 0" range="-160 20" class="stiff_medium"/>
          <geom name="lfemur" size="0.06 0.17" pos="-.01 -0.202473 0" quat="0.7 -0.7 -0.1228 -0.07"/>
          <body name="ltibia" pos="0 -0.404945 0">
            <joint name="ltibia_x" axis="1 0 0" range="1   170" class="stiff_low"/>
            <geom name="ltibia" size="0.03 0.1825614" pos="0 -0.202846 0" quat="0.7 -0.7 -0.1228 -0.1228"/>
            <geom name="lcalf" size="0.045 0.08" pos="0 -0.1 -.01" quat="0.7 -0.7 -0.1228 -0.1228"/>
            <body name="lfoot" pos="0 -0.405693 0" quat="0.707107 -0.707107 0 0">
              <!-- <site name="lfoot_touch" type="box" pos="-.005 -.02 -0.025" size=".04 .08 .02" euler="10 0 0" class="touch"/> -->
              <joint name="lfoot_z" axis="0 0 1" range="-70 20" class="stiff_medium"/>
              <joint name="lfoot_x" axis="1 0 0" range="-45    90" class="stiff_medium"/>
              <geom name="lfoot0" size="0.02 0.06" pos="-0.02 -0.023 -0.01" euler="100 -2 0"/>
              <geom name="lfoot1" size="0.02 0.06" pos="0 -0.023 -0.01" euler="100 0 0"/>
              <geom name="lfoot2" size="0.02 0.06" pos=".01 -0.023 -0.01" euler="100 10 0"/>
              <body name="ltoes" pos="0 -0.106372 -0.0227756">
                <joint name="ltoes_x" axis="1 0 0" range="-90 20"/>
                <geom name="ltoes0" type="sphere" size="0.02" pos="-.025 -0.01 -.01"/>
                <geom name="ltoes1" type="sphere" size="0.02" pos="0 -0.005 -.01"/>
                <geom name="ltoes2" type="sphere" size="0.02" pos=".02 .001 -.01"/>
                <!-- <site name="ltoes_touch" type="capsule" pos="-.005 -.005 -.01" size="0.025 0.02" zaxis="1 .2 0" class="touch"/> -->
              </body>
            </body>
          </body>
        </body>
      </body>
      <body name="rhipjoint" pos="0 0 0">
        <geom name="rhipjoint" size="0.008 0.022" pos="-0.051 -0.046 0.025" quat="0.574856 -0.547594 0.608014 0"/>
        <body name="rfemur" pos="-0.102 -0.092 0.05" quat="1 0 0 -0.17365">
          <joint name="rfemur_z" axis="0 0 1" range="-70 60" class="stiff_medium"/>
          <joint name="rfemur_y" axis="0 1 0" range="-70 70" class="stiff_medium"/>
          <joint name="rfemur_x" axis="1 0 0" range="-160 20" class="stiff_medium"/>
          <geom name="rfemur" size="0.06 0.17" pos=".01 -0.202473 0" quat="0.7 -0.7 0.1228 0.07"/>
          <body name="rtibia" pos="0 -0.404945 0">
            <joint name="rtibia_x" axis="1 0 0" range="1   170" class="stiff_low"/>
            <geom name="rtibia" size="0.03 0.1825614" pos="0 -0.202846 0" quat="0.7 -0.7 0.1228 0.1228"/>
            <geom name="rcalf" size="0.045 0.08" pos="0 -0.1 -.01" quat="0.7 -0.7 -0.1228 -0.1228"/>
            <body name="rfoot" pos="0 -0.405693 0" quat="0.707107 -0.707107 0 0">
              <!-- <site name="rfoot_touch" type="box" pos=".005 -.02 -0.025" size=".04 .08 .02" euler="10 0 0" class="touch"/> -->
              <joint name="rfoot_z" axis="0 0 1" range="-20 70" class="stiff_medium"/>
              <joint name="rfoot_x" axis="1 0 0" range="-45    90" class="stiff_medium"/>
              <geom name="rfoot0" size="0.02 0.06" pos="0.02 -0.023 -0.01" euler="100 2 0"/>
              <geom name="rfoot1" size="0.02 0.06" pos="0 -0.023 -0.01" euler="100 0 0"/>
              <geom name="rfoot2" size="0.02 0.06" pos="-.01 -0.023 -0.01" euler="100 -10 0"/>
              <body name="rtoes" pos="0 -0.106372 -0.0227756">
                <joint name="rtoes_x" axis="1 0 0" range="-90 20"/>
                <geom name="rtoes0" type="sphere" size="0.02" pos=".025 -0.01 -.01"/>
                <geom name="rtoes1" type="sphere" size="0.02" pos="0 -0.005 -.01"/>
                <geom name="rtoes2" type="sphere" size="0.02" pos="-.02 .001 -.01"/>
                <!-- <site name="rtoes_touch" type="capsule" pos=".005 -.005 -.01" size="0.025 0.02" zaxis="1 -.2 0" class="touch"/> -->
              </body>
            </body>
          </body>
        </body>
      </body>
      <body name="lowerback">
        <joint name="lowerback_z" axis="0 0 1" range="-30 30" class="stiff_high"/>
        <joint name="lowerback_y" axis="0 1 0" range="-30 30" class="stiff_high"/>
        <joint name="lowerback_x" axis="1 0 0" range="-20 45" class="stiff_high"/>
        <geom name="lowerback" size="0.065 0.055" pos="0 0.056 .03" quat="1 0 1 0"/>
        <body name="upperback" pos="0 0.1 -0.01">
          <joint name="upperback_z" axis="0 0 1" range="-30 30" class="stiff_high"/>
          <joint name="upperback_y" axis="0 1 0" range="-30 30" class="stiff_high"/>
          <joint name="upperback_x" axis="1 0 0" range="-20 45" class="stiff_high"/>
          <geom name="upperback" size="0.06 0.06" pos="0 0.06 0.02" quat="1 0 1 0"/>
          <body name="thorax" pos="0.000512528 0.11356 0.000936821">
            <joint name="thorax_z" axis="0 0 1" range="-30 30" class="stiff_high"/>
            <joint name="thorax_y" axis="0 1 0" range="-30 30" class="stiff_high"/>
            <joint name="thorax_x" axis="1 0 0" range="-20 45" class="stiff_high"/>
            <geom name="thorax" size="0.08 0.07" pos="0 0.05 0" quat="1 0 1 0"/>
            <body name="lowerneck" pos="0 0.113945 0.00468037">
              <joint name="lowerneck_z" axis="0 0 1" range="-30 30" class="stiff_medium"/>
              <joint name="lowerneck_y" axis="0 1 0" range="-30 30" class="stiff_medium"/>
              <joint name="lowerneck_x" axis="1 0 0" range="-20 45" class="stiff_medium"/>
              <geom name="lowerneck" size="0.08 0.02" pos="0 0.04 -.02" quat="1 1 0 0"/>
              <body name="upperneck" pos="0 0.09 0.01">
                <joint name="upperneck_z" axis="0 0 1" range="-30 30" class="stiff_medium"/>
                <joint name="upperneck_y" axis="0 1 0" range="-30 30" class="stiff_medium"/>
                <joint name="upperneck_x" axis="1 0 0" range="-20 45" class="stiff_medium"/>
                <geom name="upperneck" size="0.05 0.03" pos="0 0.05 0" quat=".8 1 0 0"/>
                <body name="head" pos="0 0.09 0">
                  <camera name="egocentric" pos="0 0 0" xyaxes="-1 0 0 0 1 0" fovy="80"/>
                  <joint name="head_z" axis="0 0 1" range="-30 30" class="stiff_medium"/>
                  <joint name="head_y" axis="0 1 0" range="-30 30" class="stiff_medium"/>
                  <joint name="head_x" axis="1 0 0" range="-20 45" class="stiff_medium"/>
                  <geom name="head" size="0.085 0.035" pos="0 0.11 0.03" quat="1 .9 0 0"/>
                  <geom name="leye" type="sphere" size="0.02" pos=".03 0.11 0.1"/>
                  <geom name="reye" type="sphere" size="0.02" pos="-.03 0.11 0.1"/>
                </body>
              </body>
            </body>
            <body name="lclavicle" pos="0 0.113945 0.00468037">
              <joint name="lclavicle_z" axis="0 0 1" range="0 20" class="stiff_high"/>
              <joint name="lclavicle_y" axis="0 1 0" range="-20 10" class="stiff_high"/>
              <geom name="lclavicle" size="0.08 0.04" pos="0.09 0.05 -.01" quat="1 0 -1 -.4"/>
              <body name="lhumerus" pos="0.183 0.076 0.01" quat="0.18 0.68 -0.68 0.18">
                <joint name="lhumerus_z" axis="0 0 1" range="-90 90" class="stiff_low"/>
                <joint name="lhumerus_y" axis="0 1 0" range="-90 90" class="stiff_low"/>
                <joint name="lhumerus_x" axis="1 0 0" range="-60 90" class="stiff_low"/>
                <geom name="lhumerus" size="0.035 0.124" pos="0 -0.138 0" quat="0.612 -0.612 0.35 0.35"/>
                <body name="lradius" pos="0 -0.277 0">
                  <joint name="lradius_x" axis="1 0 0" range="-10 170" class="stiff_low"/>
                  <geom name="lradius" size="0.03 0.06" pos="0 -0.08 0" quat="0.612 -0.612 0.35 0.35"/>
                  <body name="lwrist" pos="0 -0.17 0" quat="-0.5 0 0.866 0">
                    <joint name="lwrist_y" axis="0 1 0" range="-180 0"/>
                    <geom name="lwrist" size="0.025 0.03" pos="0 -0.02 0" quat="0 0 -1 -1"/>
                    <body name="lhand" pos="0 -0.08 0">
                      <joint name="lhand_z" axis="0 0 1" range="-45 45"/>
                      <joint name="lhand_x" axis="1 0 0" range="-90 90"/>
                      <geom name="lhand" type="ellipsoid" size=".048 0.02 0.06" pos="0 -0.047 0" quat="0 0 -1 -1"/>
                      <body name="lfingers" pos="0 -0.08 0">
                        <joint name="lfingers_x" axis="1 0 0" range="0 90"/>
                        <geom name="lfinger0" size="0.01 0.04" pos="-.03 -0.05 0" quat="1 -1 0 0" />
                        <geom name="lfinger1" size="0.01 0.04" pos="-.008 -0.06 0" quat="1 -1 0 0" />
                        <geom name="lfinger2" size="0.009 0.04" pos=".014 -0.06 0" quat="1 -1 0 0" />
                        <geom name="lfinger3" size="0.008 0.04" pos=".032 -0.05 0" quat="1 -1 0 0" />
                      </body>
                      <body name="lthumb" pos="-.02 -.03 0" quat="0.92388 0 0 -0.382683">
                        <joint name="lthumb_z" axis="0 0 1" range="-45 45"/>
                        <joint name="lthumb_x" axis="1 0 0" range="0 90"/>
                        <geom name="lthumb" size="0.012 0.04" pos="0 -0.06 0" quat="0 0 -1 -1"/>
                      </body>
                    </body>
                  </body>
                </body>
              </body>
            </body>
            <body name="rclavicle" pos="0 0.113945 0.00468037">
              <joint name="rclavicle_z" axis="0 0 1" range="-20 0" class="stiff_high"/>
              <joint name="rclavicle_y" axis="0 1 0" range="-10 20" class="stiff_high"/>
              <geom name="rclavicle" size="0.08 0.04" pos="-.09 0.05 -.01" quat="1 0 -1 .4"/>
              <body name="rhumerus" pos="-0.183 0.076 0.01" quat="0.18 0.68 0.68 -0.18">
                <joint name="rhumerus_z" axis="0 0 1" range="-90 90" class="stiff_low"/>
                <joint name="rhumerus_y" axis="0 1 0" range="-90 90" class="stiff_low"/>
                <joint name="rhumerus_x" axis="1 0 0" range="-60 90" class="stiff_low"/>
                <geom name="rhumerus" size="0.035 0.124" pos="0 -0.138 0" quat="0.61 -0.61 -0.35 -0.35"/>
                <body name="rradius" pos="0 -0.277 0">
                  <joint name="rradius_x" axis="1 0 0" range="-10 170" class="stiff_low"/>
                  <geom name="rradius" size="0.03 0.06" pos="0 -0.08 0" quat="0.612 -0.612 -0.35 -0.35"/>
                  <body name="rwrist" pos="0 -0.17 0" quat="-0.5 0 -0.866 0">
                    <joint name="rwrist_y" axis="0 1 0" range="-180 0"/>
                    <geom name="rwrist" size="0.025 0.03" pos="0 -0.02 0" quat="0 0 1 1"/>
                    <body name="rhand" pos="0 -0.08 0">
                      <joint name="rhand_z" axis="0 0 1" range="-45 45"/>
                      <joint name="rhand_x" axis="1 0 0" range="-90 90"/>
                      <geom name="rhand" type="ellipsoid" size=".048 0.02 .06" pos="0 -0.047 0" quat="0 0 1 1"/>
                      <body name="rfingers" pos="0 -0.08 0">
                        <joint name="rfingers_x" axis="1 0 0" range="0 90"/>
                        <geom name="rfinger0" size="0.01 0.04" pos=".03 -0.05 0" quat="1 -1  0 0" />
                        <geom name="rfinger1" size="0.01 0.04" pos=".008 -0.06 0" quat="1 -1  0 0" />
                        <geom name="rfinger2" size="0.009 0.04" pos="-.014 -0.06 0" quat="1 -1  0 0" />
                        <geom name="rfinger3" size="0.008 0.04" pos="-.032 -0.05 0" quat="1 -1  0 0" />
                      </body>
                      <body name="rthumb" pos=".02 -.03 0" quat="0.92388 0 0 0.382683">
                        <joint name="rthumb_z" axis="0 0 1" range="-45    45"/>
                        <joint name="rthumb_x" axis="1 0 0" range="0 90"/>
                        <geom name="rthumb" size="0.012 0.04" pos="0 -0.06 0" quat="0 0 1 1"/>
                      </body>
                    </body>
                  </body>
                </body>
              </body>
            </body>
          </body>
        </body>
      </body>
    </body>
  </worldbody>

  <contact>
    <exclude body1="lclavicle" body2="rclavicle"/>
    <exclude body1="lowerneck" body2="lclavicle"/>
    <exclude body1="lowerneck" body2="rclavicle"/>
    <exclude body1="upperneck" body2="lclavicle"/>
    <exclude body1="upperneck" body2="rclavicle"/>
  </contact>

  <actuator>
    <motor name="head_x" joint="head_x" gear="20"/>
    <motor name="head_y" joint="head_y" gear="20"/>
    <motor name="head_z" joint="head_z" gear="20"/>
    <motor name="lclavicle_y" joint="lclavicle_y" gear="20"/>
    <motor name="lclavicle_z" joint="lclavicle_z" gear="20"/>
    <motor name="lfemur_x" joint="lfemur_x" gear="120"/>
    <motor name="lfemur_y" joint="lfemur_y" gear="40"/>
    <motor name="lfemur_z" joint="lfemur_z" gear="40"/>
    <motor name="lfingers_x" joint="lfingers_x" gear="20"/>
    <motor name="lfoot_x" joint="lfoot_x" gear="20"/>
    <motor name="lfoot_z" joint="lfoot_z" gear="20"/>
    <motor name="lhand_x" joint="lhand_x" gear="20"/>
    <motor name="lhand_z" joint="lhand_z" gear="20"/>
    <motor name="lhumerus_x" joint="lhumerus_x" gear="40"/>
    <motor name="lhumerus_y" joint="lhumerus_y" gear="40"/>
    <motor name="lhumerus_z" joint="lhumerus_z" gear="40"/>
    <motor name="lowerback_x" joint="lowerback_x" gear="40"/>
    <motor name="lowerback_y" joint="lowerback_y" gear="40"/>
    <motor name="lowerback_z" joint="lowerback_z" gear="40"/>
    <motor name="lowerneck_x" joint="lowerneck_x" gear="20"/>
    <motor name="lowerneck_y" joint="lowerneck_y" gear="20"/>
    <motor name="lowerneck_z" joint="lowerneck_z" gear="20"/>
    <motor name="lradius_x" joint="lradius_x" gear="40"/>
    <motor name="lthumb_x" joint="lthumb_x" gear="20"/>
    <motor name="lthumb_z" joint="lthumb_z" gear="20"/>
    <motor name="ltibia_x" joint="ltibia_x" gear="80"/>
    <motor name="ltoes_x" joint="ltoes_x" gear="20"/>
    <motor name="lwrist_y" joint="lwrist_y" gear="20"/>
    <motor name="rclavicle_y" joint="rclavicle_y" gear="20"/>
    <motor name="rclavicle_z" joint="rclavicle_z" gear="20"/>
    <motor name="rfemur_x" joint="rfemur_x" gear="120"/>
    <motor name="rfemur_y" joint="rfemur_y" gear="40"/>
    <motor name="rfemur_z" joint="rfemur_z" gear="40"/>
    <motor name="rfingers_x" joint="rfingers_x" gear="20"/>
    <motor name="rfoot_x" joint="rfoot_x" gear="20"/>
    <motor name="rfoot_z" joint="rfoot_z" gear="20"/>
    <motor name="rhand_x" joint="rhand_x" gear="20"/>
    <motor name="rhand_z" joint="rhand_z" gear="20"/>
    <motor name="rhumerus_x" joint="rhumerus_x" gear="40"/>
    <motor name="rhumerus_y" joint="rhumerus_y" gear="40"/>
    <motor name="rhumerus_z" joint="rhumerus_z" gear="40"/>
    <motor name="rradius_x" joint="rradius_x" gear="40"/>
    <motor name="rthumb_x" joint="rthumb_x" gear="20"/>
    <motor name="rthumb_z" joint="rthumb_z" gear="20"/>
    <motor name="rtibia_x" joint="rtibia_x" gear="80"/>
    <motor name="rtoes_x" joint="rtoes_x" gear="20"/>
    <motor name="rwrist_y" joint="rwrist_y" gear="20"/>
    <motor name="thorax_x" joint="thorax_x" gear="40"/>
    <motor name="thorax_y" joint="thorax_y" gear="40"/>
    <motor name="thorax_z" joint="thorax_z" gear="40"/>
    <motor name="upperback_x" joint="upperback_x" gear="40"/>
    <motor name="upperback_y" joint="upperback_y" gear="40"/>
    <motor name="upperback_z" joint="upperback_z" gear="40"/>
    <motor name="upperneck_x" joint="upperneck_x" gear="20"/>
    <motor name="upperneck_y" joint="upperneck_y" gear="20"/>
    <motor name="upperneck_z" joint="upperneck_z" gear="20"/>
  </actuator>

  <sensor>
    <subtreelinvel name="thorax_subtreelinvel" body="thorax"/>
    <!-- <velocimeter name="sensor_root_veloc" site="root"/>
    <gyro name="sensor_root_gyro" site="root"/>
    <accelerometer name="sensor_root_accel" site="root"/>
    <touch name="sensor_touch_ltoes" site="ltoes_touch"/>
    <touch name="sensor_touch_rtoes" site="rtoes_touch"/>
    <touch name="sensor_touch_rfoot" site="rfoot_touch"/>
    <touch name="sensor_touch_lfoot" site="lfoot_touch"/> -->
  </sensor>

</mujoco>