<mujoco model="humanoid">
  <compiler angle="radian"/>
  <option timestep="0.00222222"/>
  <size nuser_body="3"/>
  <include file="./common/materials.xml" />
  <visual>
    <quality shadowsize="2048"/>
    <headlight ambient="0.4 0.4 0.4" diffuse="0.8 0.8 0.8" specular="0.3 0.3 0.3"/>
  </visual>
  <statistic extent="3" center="0 0 1"/>
  <default class="main">
    <joint limited="true" armature="0.01"/>
    <geom contype="7" conaffinity="7" condim="1" margin="0.001" material="self" rgba="0.98 0.54 0.56 1"/>
  </default>
    <asset>
    <texture type="skybox" file="./common/sky1.png" gridsize="3 4" gridlayout=".U..LFRB.D.." width="8192" height="8192" />
    <texture builtin="flat" height="1278" mark="cross" markrgb="1 1 1" name="texgeom" random="0.01" rgb1=".8 .6 .4" rgb2=".8 .6 .4" type="cube" width="127" />
  </asset>
  <worldbody>
    <geom name="floor" size="117.026 117.026 0.234051" pos="0 0 -1.3" type="plane" condim="3" friction="1 0.1 0.1" material="grid_new" rgba="0.8 0.9 0.8 1"/>
    <light pos="0 0 1.3" dir="0 0 -1" directional="true" cutoff="100" exponent="1" diffuse="1 1 1" specular="0.1 0.1 0.1"/>
    <body name="root" pos="0 0 0" >
      <joint name="root" pos="0 0 0" axis="0 0 1" limited="false" stiffness="1000" armature="0"/>
      <geom size="0.128728" pos="0 0 -0.0280861" mass="8.8725"/>
      <body name="lhipjoint" pos="0 0 0"  user="0.0963 -0.0494 -0.0918">
        <body name="lfemur" pos="0.112696 -0.0578106 -0.107429"  user="0.2274 -0.0494 -0.4521">
          <joint name="lfemur_z" pos="0 0 0" axis="0 -1 0" range="-1.0472 1.22173"/>
          <joint name="lfemur_y" pos="0 0 0" axis="-0.342 0 0.9397" range="-1.22173 1.22173"/>
          <joint name="lfemur_x" pos="0 0 0" axis="0.9397 0 0.342" range="-2.79253 0.349066"/>
          <geom size="0.0608533 0.200948" pos="0.0767102 0 -0.210822" quat="0.984797 0 -0.173711 0" type="capsule" mass="10.8525"/>
          <body name="ltibia" pos="0.15342 0 -0.421643"  user="0.3657 -0.0494 -0.8321">
            <joint name="ltibia_x" pos="0 0 0" axis="0.9397 0 0.342" range="0 2.96706"/>
            <geom size="0.0432995 0.213201" pos="0.0809817 0 -0.222349" quat="0.984813 0 -0.173618 0" type="capsule" contype="1" conaffinity="1" mass="3.4275"/>
            <body name="lfoot" pos="0.161846 0 -0.444697"  user="0.3731 -0.1606 -0.8523">
              <joint name="lfoot_z" pos="0 0 0" axis="-0.342 0 0.9397" range="-1.22173 0.349066"/>
              <joint name="lfoot_y" pos="0 0 0" axis="0 -1 0" range="-0.785398 0.785398"/>
              <joint name="lfoot_x" pos="0 0 0" axis="0.9397 0 0.342" range="-0.785398 1.5708"/>
              <geom size="0.0702153 0.125217 0.0280861" pos="0.00667046 -0.0580447 -0.0141601" quat="0.984816 0 -0.173603 0" type="box" contype="1" conaffinity="1" mass="0.9975"/>
            </body>
          </body>
        </body>
      </body>
    </body>
  </worldbody>
  <actuator>
    <general name="lfemur_z" joint="lfemur_z" gear="200 0 0 0 0 0" />
    <general name="lfemur_y" joint="lfemur_y" gear="200 0 0 0 0 0" />
    <general name="lfemur_x" joint="lfemur_x" gear="200 0 0 0 0 0" />
    <general name="ltibia_x" joint="ltibia_x" gear="200 0 0 0 0 0" />
    <general name="lfoot_z" joint="lfoot_z" gear="200 0 0 0 0 0" />
    <general name="lfoot_y" joint="lfoot_y" gear="200 0 0 0 0 0" />
    <general name="lfoot_x" joint="lfoot_x" gear="200 0 0 0 0 0" />
  </actuator>
</mujoco>
