<?xml version='1.0' encoding='utf-8'?>
<mujoco model="humanoid">
  <include file="./common/materials.xml" /><compiler angle="radian" inertiafromgeom="false" coordinate="local" />
  <option timestep="0.00222222" />
  <size nuser_body="3" />
  <visual>
    <quality shadowsize="2048" />
    <headlight ambient="0.4 0.4 0.4" diffuse="0.8 0.8 0.8" specular="0.3 0.3 0.3" />
  </visual>
  <statistic extent="3" center="0 0 1" />
  <default class="main">
    <joint limited="true" armature="0.01" />
    <geom contype="7" conaffinity="7" condim="1" margin="0.001" material="self" rgba="0.98 0.54 0.56 1" />
  </default>
  <worldbody>
    <geom name="floor" size="100 100 0.2" type="plane" condim="3" friction="1 0.1 0.1" material="grid_new" rgba="0.8 0.9 0.8 1" />
    <light pos="0 0 1.3" dir="0 0 -1" directional="true" cutoff="100" exponent="1" diffuse="1 1 1" specular="0.1 0.1 0.1" />
    <body name="root" pos="0 0 0">
      <joint name="root" limited="false" type="free" armature="0" />
      <geom size="0.11" pos="0 0 -0.024" />
      <body name="lhipjoint" pos="0 0 0" user="0.0963 -0.0494 -0.0918">
        <body name="lfemur" pos="0.0963 -0.0494 -0.0918" user="0.2274 -0.0494 -0.4521">
          <joint name="lfemur_z" pos="0 0 0" axis="0 -1 0" range="-1.0472 1.22173" />
          <joint name="lfemur_y" pos="0 0 0" axis="-0.342 0 0.9397" range="-1.22173 1.22173" />
          <joint name="lfemur_x" pos="0 0 0" axis="0.9397 0 0.342" range="-2.79253 0.349066" />
          <geom size="0.052 0.171713" pos="0.06555 0 -0.18015" quat="0.984797 0 -0.173711 0" type="capsule" />
          <body name="ltibia" pos="0.1311 0 -0.3603" user="0.3657 -0.0494 -0.8321">
            <joint name="ltibia_x" pos="0 0 0" axis="0.9397 0 0.342" range="0 2.96706" />
            <geom size="0.037 0.182183" pos="0.0692 0 -0.19" quat="0.984813 0 -0.173618 0" type="capsule" contype="1" conaffinity="1" />
            <body name="lfoot" pos="0.1383 0 -0.38" user="0.3731 -0.1606 -0.8523">
              <joint name="lfoot_z" pos="0 0 0" axis="-0.342 0 0.9397" range="-1.22173 0.349066" />
              <joint name="lfoot_y" pos="0 0 0" axis="0 -1 0" range="-0.785398 0.785398" />
              <joint name="lfoot_x" pos="0 0 0" axis="0.9397 0 0.342" range="-0.785398 1.5708" />
              <geom size="0.06 0.107 0.024" pos="0.0057 -0.0496 -0.0121" quat="0.984816 0 -0.173603 0" type="box" contype="1" conaffinity="1" />
            <inertial pos="0.0057 -0.0496 -0.0121" mass="0.7250000000000001" diaginertia="0.006067891288124998 0.0030339456440624988 0.006067891288124997" quat="1.0 1.942890293094024e-16 0.0 0.0" /></body>
          <inertial pos="0.06168664797045345 0.0 -0.16935329958796078" mass="2.325" diaginertia="0.023925655001321287 0.011401646090834786 0.023925655001321287" quat="0.4055975294275215 0.5792155420241163 -0.5792155420241163 -0.4055975294275215" /></body>
        <inertial pos="0.058464765355756135 0.0 -0.16069119585621164" mass="5.0" diaginertia="0.051978304125958615 0.05197830412595861 0.02491703804130353" quat="0.16195067694523765 0.3561876322668323 0.9181257422019283 0.06282889751766461" /></body>
      </body>
      <body name="rhipjoint" pos="0 0 0" user="-0.0963 -0.0494 -0.0918">
        <body name="rfemur" pos="-0.0963 -0.0494 -0.0918" user="-0.2274 -0.0494 -0.4521">
          <joint name="rfemur_z" pos="0 0 0" axis="0 -1 0" range="-1.22173 1.0472" />
          <joint name="rfemur_y" pos="0 0 0" axis="0.342 0 0.9397" range="-1.22173 1.22173" />
          <joint name="rfemur_x" pos="0 0 0" axis="0.9397 0 -0.342" range="-2.79253 0.349066" />
          <geom size="0.052 0.171713" pos="-0.06555 0 -0.18015" quat="0.984797 0 0.173711 0" type="capsule" />
          <body name="rtibia" pos="-0.1311 0 -0.3603" user="-0.3657 -0.0494 -0.8321">
            <joint name="rtibia_x" pos="0 0 0" axis="0.9397 0 -0.342" range="0 2.96706" />
            <geom size="0.037 0.182183" pos="-0.0692 0 -0.19" quat="0.984813 0 0.173618 0" type="capsule" contype="2" conaffinity="2" />
            <body name="rfoot" pos="-0.1383 0 -0.38" user="-0.3731 -0.1606 -0.8523">
              <joint name="rfoot_z" pos="0 0 0" axis="0.342 0 0.9397" range="-0.349066 1.22173" />
              <joint name="rfoot_y" pos="0 0 0" axis="0 -1 0" range="-0.785398 0.785398" />
              <joint name="rfoot_x" pos="0 0 0" axis="0.9397 0 -0.342" range="-0.785398 1.5708" />
              <geom size="0.06 0.107 0.024" pos="-0.0057 -0.0496 -0.0121" quat="0.984816 0 0.173603 0" type="box" contype="2" conaffinity="2" />
            <inertial pos="-0.0057 -0.0496 -0.0121" mass="0.7250000000000001" diaginertia="0.006067891288124998 0.0030339456440624988 0.006067891288124997" quat="1.942890293094024e-16 1.0 0.0 0.0" /></body>
          <inertial pos="-0.06168664797045345 0.0 -0.16935329958796078" mass="2.325" diaginertia="0.023925655001321287 0.011401646090834786 0.023925655001321287" quat="0.5792155420241163 -0.4055975294275215 -0.4055975294275215 0.5792155420241162" /></body>
        <inertial pos="-0.058464765355756135 0.0 -0.16069119585621164" mass="5.0" diaginertia="0.051978304125958615 0.05197830412595861 0.02491703804130353" quat="0.06282889751766461 0.9181257422019283 -0.3561876322668323 -0.16195067694523765" /></body>
      </body>
      <body name="lowerback" pos="0 0 0" user="0.0006 0.0081 0.1132">
        <body name="upperback" pos="0.0006 0.0081 0.1132" user="0.0011 0.0071 0.2268">
          <joint name="upperback_z" pos="0 0 0" axis="0 -1 0" range="-0.523599 0.523599" />
          <joint name="upperback_y" pos="0 0 0" axis="0 0 1" range="-0.523599 0.523599" />
          <joint name="upperback_x" pos="0 0 0" axis="1 0 0" range="-0.349066 0.785398" />
          <geom size="0.07" pos="0 0 0.01" />
          <body name="thorax" pos="0.0005 -0.001 0.1136" user="0.001 0.0024 0.3407">
            <geom size="0.1" pos="0 0 0.054" />
            <body name="lowerneck" pos="-0.0001 -0.0047 0.1139" user="-0.0023 -0.0083 0.4312">
              <joint name="lowerneck_z" pos="0 0 0" axis="0 -1 0" range="-0.523599 0.523599" />
              <joint name="lowerneck_y" pos="0 0 0" axis="0 0 1" range="-0.523599 0.523599" />
              <joint name="lowerneck_x" pos="0 0 0" axis="1 0 0" range="-0.349066 0.785398" />
              <geom size="0.08" pos="-0.0033 -0.0107 0.2065" />
              <body name="upperneck" pos="-0.0033 -0.0107 0.0905" user="-0.0013 -0.0038 0.5212">
                <body name="head" pos="0.001 0.0045 0.09" user="-0.0006 -0.0008 0.6176">
                  <camera pos="0.0013 0.0038 -0.5212" quat="0 0 0.707107 0.707107" />
                </body>
              </body>
              <body name="lclavicle" pos="-0.0033 -0.0107 0.0905" user="0.179 -0.0149 0.4121">
                <joint name="lclavicle_z" pos="0.0033 0.0107 -0.0905" axis="0 -1 0" range="0 0.349066" />
                <joint name="lclavicle_y" pos="0.0033 0.0107 -0.0905" axis="0 0 1" range="-0.349066 0.174533" />
                <geom size="0.034 0.0787335" pos="0.09065 -0.0033 -0.00955" quat="0.743231 -0.0239246 -0.668607 0" type="capsule" />
                <body name="lhumerus" pos="0.1813 -0.0066 -0.0191" user="0.4599 -0.0149 0.4121">
                  <joint name="lhumerus_z" pos="0 0 0" axis="0 0.866019 -0.500011" range="-1.5708 1.5708" />
                  <joint name="lhumerus_y" pos="0 0 0" axis="-1 0 0" range="-1.5708 1.5708" />
                  <joint name="lhumerus_x" pos="0 0 0" axis="0 -0.500011 -0.866019" range="-1.0472 1.5708" />
                  <geom size="0.031 0.12295" pos="0.14045 0 0" quat="0.707107 0 -0.707107 0" type="capsule" />
                  <body name="lradius" pos="0.2809 0 0" user="0.6374 -0.0149 0.4121">
                    <joint name="lradius_x" pos="0 0 0" axis="0 -0.500011 -0.866019" range="-0.174533 2.96706" />
                    <geom size="0.025 0.08875" pos="0.08875 0 0" quat="0.707107 0 -0.707107 0" type="capsule" />
                    <body name="lwrist" pos="0.1775 0 0" user="0.7261 -0.0149 0.4121">
                      <geom size="0.04" pos="0.044 0 0" />
                    <inertial pos="0.044 0.0 0.0" mass="0.5" diaginertia="2.5920000000000004e-07 2.5920000000000004e-07 2.5920000000000004e-07" quat="-0.5 0.5 0.5 0.5" /></body>
                  <inertial pos="0.08875 0.0 0.0" mass="0.5" diaginertia="1.2760031249999995e-06 1.2760031249999995e-06 1.2760031249999995e-06" quat="-0.5 0.5 0.5 0.5" /></body>
                <inertial pos="0.14045 0.0 0.0" mass="0.5" diaginertia="2.448905804999999e-06 2.448905804999999e-06 2.448905804999999e-06" quat="-0.5 0.5 0.5 0.5" /></body>
              <inertial pos="0.09065 -0.0033 -0.00955" mass="0.5" diaginertia="1.0042321716044999e-06 1.0042321716044994e-06 1.0042321716044999e-06" quat="0.14883929320500894 0.9888613981737954 0.0 0.0" /></body>
              <body name="rclavicle" pos="0.0013 -0.0107 0.0905" user="-0.179 -0.0149 0.4121">
                <joint name="rclavicle_z" pos="-0.0033 0.0107 -0.0905" axis="0 -1 0" range="-0.349066 0" />
                <joint name="rclavicle_y" pos="-0.0033 0.0107 -0.0905" axis="0 0 1" range="-0.174533 0.349066" />
                <geom size="0.034 0.0787335" pos="-0.09065 -0.0033 -0.00955" quat="0.743231 -0.0239246 0.668607 0" type="capsule" />
                <body name="rhumerus" pos="-0.1813 -0.0066 -0.0191" user="-0.4599 -0.0149 0.4121">
                  <joint name="rhumerus_z" pos="0 0 0" axis="0 0.866019 -0.500011" range="-1.5708 1.5708" />
                  <joint name="rhumerus_y" pos="0 0 0" axis="1 0 0" range="-1.5708 1.5708" />
                  <joint name="rhumerus_x" pos="0 0 0" axis="0 0.500011 0.866019" range="-1.5708 1.0472" />
                  <geom size="0.031 0.12295" pos="-0.14045 0 0" quat="0.707107 0 0.707107 0" type="capsule" />
                  <body name="rradius" pos="-0.2809 0 0" user="-0.6374 -0.0149 0.4121">
                    <joint name="rradius_x" pos="0 0 0" axis="0 0.500011 0.866019" range="-0.174533 2.96706" />
                    <geom size="0.025 0.08875" pos="-0.08875 0 0" quat="0.707107 0 0.707107 0" type="capsule" />
                    <body name="rwrist" pos="-0.1775 0 0" user="-0.7261 -0.0149 0.4121">
                      <geom size="0.04" pos="-0.044 0 0" />
                    <inertial pos="-0.044 0.0 0.0" mass="0.5" diaginertia="2.5920000000000004e-07 2.5920000000000004e-07 2.5920000000000004e-07" quat="-0.5 0.5 0.5 0.5" /></body>
                  <inertial pos="-0.08875 0.0 0.0" mass="0.5" diaginertia="1.2760031249999995e-06 1.2760031249999995e-06 1.2760031249999995e-06" quat="-0.5 0.5 0.5 0.5" /></body>
                <inertial pos="-0.14045 0.0 0.0" mass="0.5" diaginertia="2.448905804999999e-06 2.448905804999999e-06 2.448905804999999e-06" quat="-0.5 0.5 0.5 0.5" /></body>
              <inertial pos="-0.09065 -0.0033 -0.00955" mass="0.5" diaginertia="1.0042321716044999e-06 1.0042321716044994e-06 1.0042321716044999e-06" quat="0.14883929320500894 0.9888613981737954 0.0 0.0" /></body>
            <inertial pos="-0.0033 -0.0107 0.2065" mass="0.5" diaginertia="1.0368000000000002e-06 1.0368000000000002e-06 1.0368000000000002e-06" quat="-0.5 0.5 0.5 0.5" /></body>
          <inertial pos="0.0 0.0 0.054" mass="0.5" diaginertia="1.6200000000000004e-06 1.6200000000000004e-06 1.6200000000000004e-06" quat="-0.5 0.5 0.5 0.5" /></body>
        <inertial pos="0.0 0.0 0.01" mass="0.5" diaginertia="7.938000000000003e-07 7.938000000000003e-07 7.938000000000003e-07" quat="-0.5 0.5 0.5 0.5" /></body>
      </body>
    <inertial pos="0.0 0.0 -0.024" mass="7.1" diaginertia="4.037366417976345 4.037366417976345 4.037366417976345" quat="-0.5 0.5 0.5 0.5" /></body>
  </worldbody>
  <actuator>
    <general name="lfemur_z" joint="lfemur_z" />
    <general name="lfemur_y" joint="lfemur_y" />
    <general name="lfemur_x" joint="lfemur_x" />
    <general name="ltibia_x" joint="ltibia_x" />
    <general name="lfoot_z" joint="lfoot_z" />
    <general name="lfoot_y" joint="lfoot_y" />
    <general name="lfoot_x" joint="lfoot_x" />
    <general name="rfemur_z" joint="rfemur_z" />
    <general name="rfemur_y" joint="rfemur_y" />
    <general name="rfemur_x" joint="rfemur_x" />
    <general name="rtibia_x" joint="rtibia_x" />
    <general name="rfoot_z" joint="rfoot_z" />
    <general name="rfoot_y" joint="rfoot_y" />
    <general name="rfoot_x" joint="rfoot_x" />
    <general name="upperback_z" joint="upperback_z" />
    <general name="upperback_y" joint="upperback_y" />
    <general name="upperback_x" joint="upperback_x" />
    <general name="lowerneck_z" joint="lowerneck_z" />
    <general name="lowerneck_y" joint="lowerneck_y" />
    <general name="lowerneck_x" joint="lowerneck_x" />
    <general name="lclavicle_z" joint="lclavicle_z" />
    <general name="lclavicle_y" joint="lclavicle_y" />
    <general name="lhumerus_z" joint="lhumerus_z" />
    <general name="lhumerus_y" joint="lhumerus_y" />
    <general name="lhumerus_x" joint="lhumerus_x" />
    <general name="lradius_x" joint="lradius_x" />
    <general name="rclavicle_z" joint="rclavicle_z" />
    <general name="rclavicle_y" joint="rclavicle_y" />
    <general name="rhumerus_z" joint="rhumerus_z" />
    <general name="rhumerus_y" joint="rhumerus_y" />
    <general name="rhumerus_x" joint="rhumerus_x" />
    <general name="rradius_x" joint="rradius_x" />
  </actuator>
</mujoco>