<?xml version='1.0' encoding='utf-8'?>
<mujoco model="humanoid">
  <include file="./common/materials.xml" />
  <compiler angle="degree" inertiafromgeom="true" coordinate="local" />
  <statistic extent="3" center="0 0 1" />
  <size nuser_body="3" />
  <option timestep="0.00222222222"/>
  <default class="main">
    <joint limited="true" solimplimit="0 0.99 0.01"/>
    <geom contype="7" conaffinity="7" condim="1" margin="0.001" material="self" rgba="0.98 0.54 0.56 1" />
  </default>

  <worldbody>
    <geom condim="3" friction="1. .1 .1" material="grid_new" name="floor" pos="0.0 0.0 0.0" rgba=".8 .9 .8 1" size="117.025545004681 117.025545004681 0.23405109000936203" type="plane" />
    <light name="tracking_light" pos="0 0 7" dir="0 0 -1" mode="trackcom"/>
    <camera name="back" pos="0 3 2.4" xyaxes="-1 0 0 0 -1 2" mode="trackcom"/>
    <camera name="side" pos="-3 0 2.4" xyaxes="0 -1 0 1 0 2" mode="trackcom"/>
    <body name="root"  pos="0 0 0" euler="90 0 0">
      <joint armature="0.0" limited="false" name="root" pos="0.0 -0.0 0.0" stiffness="0" type="free" />

      <geom type="capsule" name="root_geom" size="0.09 0.06" pos="0 -0.05 0" quat="1 0 -1 0"/>
      <body name="lhipjoint" pos = "0 0 0">
        <geom type="capsule" name="lhipjoint" size="0.008 0.022" pos="0.051 -0.046 0.025" quat="0.5708 -0.566602 -0.594264 0" />
        <body name="lfemur" pos="0.102 -0.092 0.05" quat="1 0 0 0.17365">
          <joint name="lfemur_z" axis="0 0 1" range="-60 70" type="hinge"/>
          <joint name="lfemur_y" axis="0 1 0" range="-70 70" type="hinge"/>
          <joint name="lfemur_x" axis="1 0 0" range="-160 20" type="hinge"/>
          <geom type="capsule" name="lfemur" size="0.06 0.17" pos="-.01 -0.202473 0" quat="0.7 -0.7 -0.1228 -0.07"/>
          <body name="ltibia" pos="0 -0.404945 0">
            <joint name="ltibia_x" axis="1 0 0" range="1   170" type="hinge"/>
            <geom type="capsule" name="ltibia" size="0.03 0.1825614" pos="0 -0.202846 0" quat="0.7 -0.7 -0.1228 -0.1228"/>
            <geom type="capsule" name="lcalf" size="0.045 0.08" pos="0 -0.1 -.01" quat="0.7 -0.7 -0.1228 -0.1228"/>
            <body name="lfoot" pos="0 -0.405693 0" quat="0.707107 -0.707107 0 0">
              <!-- <site name="lfoot_touch" type="box" pos="-.005 -.02 -0.025" size=".04 .08 .02" euler="10 0 0" class="touch"/> -->
              <joint name="lfoot_z" axis="0 0 1" range="-70 20" type="hinge"/>
              <joint name="lfoot_y" pos="0 0 0" axis="0 -1 0" range="-45 45" />
              <joint name="lfoot_x" axis="1 0 0" range="-45    90" type="hinge"/>
              <geom type="capsule" name="lfoot0" size="0.02 0.06" pos="-0.02 -0.023 -0.01" euler="100 -2 0"/>
              <geom type="capsule" name="lfoot1" size="0.02 0.06" pos="0 -0.023 -0.01" euler="100 0 0"/>
              <geom type="capsule" name="lfoot2" size="0.02 0.06" pos=".01 -0.023 -0.01" euler="100 10 0"/>
              <body name="ltoes" pos="0 -0.106372 -0.0227756">
                <!-- <joint name="ltoes_x" axis="1 0 0" range="-90 20"/> -->
                <geom name="ltoes0" type="sphere" size="0.02" pos="-.025 -0.01 -.01"/>
                <geom name="ltoes1" type="sphere" size="0.02" pos="0 -0.005 -.01"/>
                <geom name="ltoes2" type="sphere" size="0.02" pos=".02 .001 -.01"/>
                <!-- <site name="ltoes_touch" type="capsule" pos="-.005 -.005 -.01" size="0.025 0.02" zaxis="1 .2 0" class="touch"/> -->
              </body>
            </body>
          </body>
        </body>
      </body>
      <body name="rhipjoint" pos="0 0 0">
        <geom type="capsule" name="rhipjoint" size="0.008 0.022" pos="-0.051 -0.046 0.025" quat="0.574856 -0.547594 0.608014 0"/>
        <body name="rfemur" pos="-0.102 -0.092 0.05" quat="1 0 0 -0.17365">
          <joint name="rfemur_z" axis="0 0 1" range="-70 60" type="hinge"/>
          <joint name="rfemur_y" axis="0 1 0" range="-70 70" type="hinge"/>
          <joint name="rfemur_x" axis="1 0 0" range="-160 20" type="hinge"/>
          <geom type="capsule" name="rfemur" size="0.06 0.17" pos=".01 -0.202473 0" quat="0.7 -0.7 0.1228 0.07"/>
          <body name="rtibia" pos="0 -0.404945 0">
            <joint name="rtibia_x" axis="1 0 0" range="1   170" type="hinge"/>
            <geom type="capsule" name="rtibia" size="0.03 0.1825614" pos="0 -0.202846 0" quat="0.7 -0.7 0.1228 0.1228"/>
            <geom type="capsule" name="rcalf" size="0.045 0.08" pos="0 -0.1 -.01" quat="0.7 -0.7 -0.1228 -0.1228"/>
            <body name="rfoot" pos="0 -0.405693 0" quat="0.707107 -0.707107 0 0">
              <!-- <site name="rfoot_touch" type="box" pos=".005 -.02 -0.025" size=".04 .08 .02" euler="10 0 0" class="touch"/> -->
              <joint name="rfoot_z" axis="0 0 1" range="-20 70" type="hinge"/>
              <joint name="rfoot_y" pos="0 0 0" axis="0 -1 0" range="-45 45" />
              <joint name="rfoot_x" axis="1 0 0" range="-45    90" type="hinge"/>
              <geom type="capsule" name="rfoot0" size="0.02 0.06" pos="0.02 -0.023 -0.01" euler="100 2 0"/>
              <geom type="capsule" name="rfoot1" size="0.02 0.06" pos="0 -0.023 -0.01" euler="100 0 0"/>
              <geom type="capsule" name="rfoot2" size="0.02 0.06" pos="-.01 -0.023 -0.01" euler="100 -10 0"/>
              <body name="rtoes" pos="0 -0.106372 -0.0227756">
                <!-- <joint name="rtoes_x" axis="1 0 0" range="-90 20"/> -->
                <geom  name="rtoes0" type="sphere" size="0.02" pos=".025 -0.01 -.01"/>
                <geom  name="rtoes1" type="sphere" size="0.02" pos="0 -0.005 -.01"/>
                <geom  name="rtoes2" type="sphere" size="0.02" pos="-.02 .001 -.01"/>
                <!-- <site name="rtoes_touch" type="capsule" pos=".005 -.005 -.01" size="0.025 0.02" zaxis="1 -.2 0" class="touch"/> -->
              </body>
            </body>
          </body>
        </body>
      </body>
      <body name="lowerback">
        <geom type="capsule" name="lowerback" size="0.065 0.055" pos="0 0.056 .03" quat="1 0 1 0"/>
        <body name="upperback" pos="0 0.1 -0.01">
          <joint name="upperback_z" axis="0 0 1" range="-30 30" type="hinge"/>
          <joint name="upperback_y" axis="0 1 0" range="-30 30" type="hinge"/>
          <joint name="upperback_x" axis="1 0 0" range="-20 45" type="hinge"/>
          <geom type="capsule" name="upperback" size="0.06 0.06" pos="0 0.06 0.02" quat="1 0 1 0"/>
          <body name="thorax" pos="0.000512528 0.11356 0.000936821">
            <geom type="capsule" name="thorax" size="0.08 0.07" pos="0 0.05 0" quat="1 0 1 0"/>
            <body name="lowerneck" pos="0 0.113945 0.00468037">
              <joint name="lowerneck_z" axis="0 0 1" range="-30 30" type="hinge"/>
              <joint name="lowerneck_y" axis="0 1 0" range="-30 30" type="hinge"/>
              <joint name="lowerneck_x" axis="1 0 0" range="-20 45" type="hinge"/>
              <geom type="capsule" name="lowerneck" size="0.08 0.02" pos="0 0.04 -.02" quat="1 1 0 0"/>
              <body name="upperneck" pos="0 0.09 0.01">
                <geom type="capsule" name="upperneck" size="0.05 0.03" pos="0 0.05 0" quat=".8 1 0 0"/>
                <body name="head" pos="0 0.09 0">
                  <camera name="egocentric" pos="0 0 0" xyaxes="-1 0 0 0 1 0" fovy="80"/>
                  <geom type="capsule" name="head" size="0.085 0.035" pos="0 0.11 0.03" quat="1 .9 0 0"/>
                  <geom  name="leye" type="sphere" size="0.02" pos=".03 0.11 0.1"/>
                  <geom  name="reye" type="sphere" size="0.02" pos="-.03 0.11 0.1"/>
                </body>
              </body>
            </body>
            <body name="lclavicle" pos="0 0.113945 0.00468037">
              <joint name="lclavicle_z" axis="0 0 1" range="0 20" type="hinge"/>
              <joint name="lclavicle_y" axis="0 1 0" range="-20 10" type="hinge"/>
              <geom type="capsule" name="lclavicle" size="0.08 0.04" pos="0.09 0.05 -.01" quat="1 0 -1 -.4"/>
              <body name="lhumerus" pos="0.183 0.076 0.01" quat="0.18 0.68 -0.68 0.18">
                <joint name="lhumerus_z" axis="0 0 1" range="-90 90" type="hinge"/>
                <joint name="lhumerus_y" axis="0 1 0" range="-90 90" type="hinge"/>
                <joint name="lhumerus_x" axis="1 0 0" range="-60 90" type="hinge"/>
                <geom type="capsule" name="lhumerus" size="0.035 0.124" pos="0 -0.138 0" quat="0.612 -0.612 0.35 0.35"/>
                <body name="lradius" pos="0 -0.277 0">
                  <joint name="lradius_x" axis="1 0 0" range="-10 170" type="hinge"/>
                  <geom type="capsule" name="lradius" size="0.03 0.06" pos="0 -0.08 0" quat="0.612 -0.612 0.35 0.35"/>
                  <body name="lwrist" pos="0 -0.17 0" quat="-0.5 0 0.866 0">
                    <geom type="capsule" name="lwrist" size="0.025 0.03" pos="0 -0.02 0" quat="0 0 -1 -1"/>
                    <body name="lhand" pos="0 -0.08 0">
                      <geom name="lhand" type="ellipsoid" size=".048 0.02 0.06" pos="0 -0.047 0" quat="0 0 -1 -1"/>
                      <body name="lfingers" pos="0 -0.08 0">
                        <geom type="capsule" name="lfinger0" size="0.01 0.04" pos="-.03 -0.05 0" quat="1 -1 0 0" />
                        <geom type="capsule" name="lfinger1" size="0.01 0.04" pos="-.008 -0.06 0" quat="1 -1 0 0" />
                        <geom type="capsule" name="lfinger2" size="0.009 0.04" pos=".014 -0.06 0" quat="1 -1 0 0" />
                        <geom type="capsule" name="lfinger3" size="0.008 0.04" pos=".032 -0.05 0" quat="1 -1 0 0" />
                      </body>
                      <body name="lthumb" pos="-.02 -.03 0" quat="0.92388 0 0 -0.382683">
                        <geom type="capsule" name="lthumb" size="0.012 0.04" pos="0 -0.06 0" quat="0 0 -1 -1"/>
                      </body>
                    </body>
                  </body>
                </body>
              </body>
            </body>
            <body name="rclavicle" pos="0 0.113945 0.00468037">
              <joint name="rclavicle_z" axis="0 0 1" range="-20 0" type="hinge"/>
              <joint name="rclavicle_y" axis="0 1 0" range="-10 20" type="hinge"/>
              <geom type="capsule" name="rclavicle" size="0.08 0.04" pos="-.09 0.05 -.01" quat="1 0 -1 .4"/>
              <body name="rhumerus" pos="-0.183 0.076 0.01" quat="0.18 0.68 0.68 -0.18">
                <joint name="rhumerus_z" axis="0 0 1" range="-90 90" type="hinge"/>
                <joint name="rhumerus_y" axis="0 1 0" range="-90 90" type="hinge"/>
                <joint name="rhumerus_x" axis="1 0 0" range="-60 90" type="hinge"/>
                <geom type="capsule" name="rhumerus" size="0.035 0.124" pos="0 -0.138 0" quat="0.61 -0.61 -0.35 -0.35"/>
                <body name="rradius" pos="0 -0.277 0">
                  <joint name="rradius_x" axis="1 0 0" range="-10 170" type="hinge"/>
                  <geom type="capsule" name="rradius" size="0.03 0.06" pos="0 -0.08 0" quat="0.612 -0.612 -0.35 -0.35"/>
                  <body name="rwrist" pos="0 -0.17 0" quat="-0.5 0 -0.866 0">
                    <geom type="capsule" name="rwrist" size="0.025 0.03" pos="0 -0.02 0" quat="0 0 1 1"/>
                    <body name="rhand" pos="0 -0.08 0">
                      <geom name="rhand" type="ellipsoid" size=".048 0.02 .06" pos="0 -0.047 0" quat="0 0 1 1"/>
                      <body name="rfingers" pos="0 -0.08 0">
                        <geom type="capsule" name="rfinger0" size="0.01 0.04" pos=".03 -0.05 0" quat="1 -1  0 0" />
                        <geom type="capsule" name="rfinger1" size="0.01 0.04" pos=".008 -0.06 0" quat="1 -1  0 0" />
                        <geom type="capsule" name="rfinger2" size="0.009 0.04" pos="-.014 -0.06 0" quat="1 -1  0 0" />
                        <geom type="capsule" name="rfinger3" size="0.008 0.04" pos="-.032 -0.05 0" quat="1 -1  0 0" />
                      </body>
                      <body name="rthumb" pos=".02 -.03 0" quat="0.92388 0 0 0.382683">
                        <geom name="rthumb" size="0.012 0.04" pos="0 -0.06 0" quat="0 0 1 1"/>
                      </body>
                    </body>
                  </body>
                </body>
              </body>
            </body>
          </body>
        </body>
      </body>
    </body>
  </worldbody>

  <contact>
    <exclude body1="lclavicle" body2="rclavicle"/>
    <exclude body1="lowerneck" body2="lclavicle"/>
    <exclude body1="lowerneck" body2="rclavicle"/>
    <exclude body1="upperneck" body2="lclavicle"/>
    <exclude body1="upperneck" body2="rclavicle"/>
  </contact>

  <actuator>
    <general name="lfemur_z" joint="lfemur_z" />
    <general name="lfemur_y" joint="lfemur_y" />
    <general name="lfemur_x" joint="lfemur_x" />
    <general name="ltibia_x" joint="ltibia_x" />
    <general name="lfoot_z" joint="lfoot_z" />
    <general name="lfoot_y" joint="lfoot_y" />
    <general name="lfoot_x" joint="lfoot_x" />
    <general name="rfemur_z" joint="rfemur_z" />
    <general name="rfemur_y" joint="rfemur_y" />
    <general name="rfemur_x" joint="rfemur_x" />
    <general name="rtibia_x" joint="rtibia_x" />
    <general name="rfoot_z" joint="rfoot_z" />
    <general name="rfoot_y" joint="rfoot_y" />
    <general name="rfoot_x" joint="rfoot_x" />
    <general name="upperback_z" joint="upperback_z" />
    <general name="upperback_y" joint="upperback_y" />
    <general name="upperback_x" joint="upperback_x" />
    <general name="lowerneck_z" joint="lowerneck_z" />
    <general name="lowerneck_y" joint="lowerneck_y" />
    <general name="lowerneck_x" joint="lowerneck_x" />
    <general name="lclavicle_z" joint="lclavicle_z" />
    <general name="lclavicle_y" joint="lclavicle_y" />
    <general name="lhumerus_z" joint="lhumerus_z" />
    <general name="lhumerus_y" joint="lhumerus_y" />
    <general name="lhumerus_x" joint="lhumerus_x" />
    <general name="lradius_x" joint="lradius_x" />
    <general name="rclavicle_z" joint="rclavicle_z" />
    <general name="rclavicle_y" joint="rclavicle_y" />
    <general name="rhumerus_z" joint="rhumerus_z" />
    <general name="rhumerus_y" joint="rhumerus_y" />
    <general name="rhumerus_x" joint="rhumerus_x" />
    <general name="rradius_x" joint="rradius_x" />
  </actuator>
</mujoco>