<mujoco model="humanoid">
  <compiler angle="degree" inertiafromgeom="true" coordinate="global" />
  <include file="./common/materials.xml" />
    <visual>
    <headlight ambient=".4 .4 .4" diffuse=".8 .8 .8" specular="0.3 0.3 0.3" />
    <map znear=".01" />
    <quality shadowsize="2048" />
  </visual>
  <default>
    <joint damping="0.0" armature="0.01" stiffness="0.0" limited="true" />
    <geom conaffinity="7" condim="1" contype="7" margin="0.001" material="self" rgba=".98 .54 .56 1." />
  </default>
  <statistic extent="3" center="0 0 1" />
  <option timestep="0.00222222222" />
  <asset>
    <texture type="skybox" file="./common/sky1.png" gridsize="3 4" gridlayout=".U..LFRB.D.." width="8192" height="8192" />
    <texture builtin="flat" height="1278" mark="cross" markrgb="1 1 1" name="texgeom" random="0.01" rgb1=".8 .6 .4" rgb2=".8 .6 .4" type="cube" width="127" />
  </asset>
  <worldbody>
    <light cutoff="100" diffuse="1 1 1" dir="-0 0 -1.3" directional="true" exponent="1" pos="0 0 1.3" specular=".1 .1 .1" />
    <geom condim="3" friction="1. .1 .1" material="grid_new" name="floor" pos="0.0 0.0 -1.3" rgba=".8 .9 .8 1" size="117.025545004681 117.025545004681 0.23405109000936203" type="plane" />
    
    <body name="root" user="0.0000 -0.0000 0.0000" pos="0.0 -0.0 0.0">
      <joint armature="0.0" limited="false" name="root" pos="0.0 -0.0 0.0" stiffness="1e3" type="hinge" />
      <geom pos="0.0 0.0 -0.028086130801123443" size="0.1287280995051491" type="sphere" mass="8.8725" />
      <body name="lhipjoint" user="0.0963 -0.0494 -0.0918" pos="0.0 -0.0 0.0">
        <body name="lfemur" user="0.2274 -0.0494 -0.4521" pos="0.1126955998395078 -0.05781061923231242 -0.10742945031429717">
          <joint axis="0.0000 -1.0000 0.0000" name="lfemur_z" pos="0.1126955998395078 -0.05781061923231242 -0.10742945031429717" range="-60.0000 70.0000" type="hinge" />
          <joint axis="-0.3420 -0.0000 0.9397" name="lfemur_y" pos="0.1126955998395078 -0.05781061923231242 -0.10742945031429717" range="-70.0000 70.0000" type="hinge" />
          <joint axis="0.9397 0.0000 0.3420" name="lfemur_x" pos="0.1126955998395078 -0.05781061923231242 -0.10742945031429717" range="-160.0000 20.0000" type="hinge" />
          <geom fromto="0.12065333689982612 -0.05781061923231242 -0.1294302527751772 0.2581583522803263 -0.05781061923231242 -0.5070716865052828" size="0.06085328340243412" type="capsule" mass="10.8525" />
          <body name="ltibia" user="0.3657 -0.0494 -0.8321" pos="0.2661160893406446 -0.05781061923231242 -0.5290724889661629">
            <joint axis="0.9397 0.0000 0.3420" name="ltibia_x" pos="0.2661160893406446 -0.05781061923231242 -0.5290724889661629" range="0.0000 170.0000" type="hinge" />
            <geom contype="1" conaffinity="1" fromto="0.2741908519459676 -0.05781061923231242 -0.5510732914270429 0.42000468102180016 -0.05781061923231242 -0.9517687575230707" size="0.04329945165173197" type="capsule" mass="3.4274999999999998" />
            <body name="lfoot" user="0.3731 -0.1606 -0.8523" pos="0.4279624180821185 -0.05781061923231242 -0.9737695599839506">
              <geom contype="1" conaffinity="1" pos="0.4346328741473853 -0.1158552895546342 -0.987929650929517" size="0.07021532700280861 0.1252173331550087 0.028086130801123443" quat="0.9848 -0.0000 -0.1736 0.0000" type="box" mass="0.9974999999999999" />
              <joint axis="-0.3420 -0.0000 0.9397" name="lfoot_z" pos="0.4279624180821185 -0.05781061923231242 -0.9737695599839506" range="-70.0000 20.0000" type="hinge" />
              <joint axis="0.0000 -1.0000 0.0000" name="lfoot_y" pos="0.4279624180821185 -0.05781061923231242 -0.9737695599839506" range="-45.0000 45.0000" type="hinge" />
              <joint axis="0.9397 0.0000 0.3420" name="lfoot_x" pos="0.4279624180821185 -0.05781061923231242 -0.9737695599839506" range="-45.0000 90.0000" type="hinge" />
            </body>
          </body>
        </body>
      </body>
    </body>
  </worldbody>
  <actuator>
    <motor gear="200" joint="lfemur_z" name="lfemur_z" /> 
    <motor gear="200" joint="lfemur_y" name="lfemur_y" />
    <motor gear="200" joint="lfemur_x" name="lfemur_x" />
    <motor gear="200" joint="ltibia_x" name="ltibia_x" />
    <motor gear="200" joint="lfoot_z" name="lfoot_z" />
    <motor gear="200" joint="lfoot_y" name="lfoot_y" />
    <motor gear="200" joint="lfoot_x" name="lfoot_x" />
  </actuator>
</mujoco>